[2016-11-01 11:58:23] DEBUG [django.db.backends:89] (0.002) 
            SELECT name, type FROM sqlite_master
            WHERE type in ('table', 'view') AND NOT name='sqlite_sequence'
            ORDER BY name; args=None
[2016-11-01 11:58:23] DEBUG [django.db.backends:89] (0.001) SELECT "django_migrations"."app", "django_migrations"."name" FROM "django_migrations"; args=()
[2016-11-01 11:58:31] DEBUG [django.db.backends:89] (0.001) SELECT "oauth2_provider_application"."id", "oauth2_provider_application"."client_id", "oauth2_provider_application"."user_id", "oauth2_provider_application"."redirect_uris", "oauth2_provider_application"."client_type", "oauth2_provider_application"."authorization_grant_type", "oauth2_provider_application"."client_secret", "oauth2_provider_application"."name", "oauth2_provider_application"."skip_authorization" FROM "oauth2_provider_application" WHERE "oauth2_provider_application"."client_id" = '1mDR3zdKmNxeMHoqSJfOfX4JBwSvw93zRK2GaZ61'; args=('1mDR3zdKmNxeMHoqSJfOfX4JBwSvw93zRK2GaZ61',)
[2016-11-01 12:00:13] WARNING [django.request:182] Not Found: /
[2016-11-01 12:00:13] DEBUG [django.template:927] Exception while resolving variable 'name' in template 'unknown'.
Traceback (most recent call last):
  File "D:\pydev\marketsoft\ve_market\lib\site-packages\django\core\handlers\base.py", line 134, in get_response
    resolver_match = resolver.resolve(request.path_info)
  File "D:\pydev\marketsoft\ve_market\lib\site-packages\django\core\urlresolvers.py", line 404, in resolve
    raise Resolver404({'tried': tried, 'path': new_path})
django.core.urlresolvers.Resolver404: {'tried': [[<RegexURLResolver <RegexURLPattern list> (admin:admin) ^admin/>], [<RegexURLResolver <module 'django.contrib.admindocs.urls' from 'D:\\pydev\\marketsoft\\ve_market\\lib\\site-packages\\django\\contrib\\admindocs\\urls.py'> (None:None) ^admin/doc/>], [<RegexURLResolver <module 'rest_framework.urls' from 'D:\\pydev\\marketsoft\\ve_market\\lib\\site-packages\\rest_framework\\urls.py'> (rest_framework:rest_framework) ^api-auth/>], [<RegexURLResolver <module 'oauth2_provider.urls' from 'D:\\pydev\\marketsoft\\ve_market\\lib\\site-packages\\oauth2_provider\\urls.py'> (None:oauth2_provider) ^o/>], [<RegexURLResolver <module 'ioteca_service_apps.auths_api.urls' from 'D:\\pydev\\marketsoft\\ioteca_service\\ioteca_service_apps\\auths_api\\urls.py'> (None:None) ^api/auths/>], [<RegexURLResolver <module 'ioteca_service_apps.catalogo_api.urls' from 'D:\\pydev\\marketsoft\\ioteca_service\\ioteca_service_apps\\catalogo_api\\urls.py'> (None:None) ^api/catalogo/>]], 'path': ''}

During handling of the above exception, another exception occurred:

Traceback (most recent call last):
  File "D:\pydev\marketsoft\ve_market\lib\site-packages\django\template\base.py", line 883, in _resolve_lookup
    current = current[bit]
TypeError: 'RegexURLResolver' object is not subscriptable

During handling of the above exception, another exception occurred:

Traceback (most recent call last):
  File "D:\pydev\marketsoft\ve_market\lib\site-packages\django\template\base.py", line 891, in _resolve_lookup
    current = getattr(current, bit)
AttributeError: 'RegexURLResolver' object has no attribute 'name'

During handling of the above exception, another exception occurred:

Traceback (most recent call last):
  File "D:\pydev\marketsoft\ve_market\lib\site-packages\django\template\base.py", line 898, in _resolve_lookup
    current = current[int(bit)]
ValueError: invalid literal for int() with base 10: 'name'

During handling of the above exception, another exception occurred:

Traceback (most recent call last):
  File "D:\pydev\marketsoft\ve_market\lib\site-packages\django\template\base.py", line 905, in _resolve_lookup
    (bit, current))  # missing attribute
django.template.base.VariableDoesNotExist: Failed lookup for key [name] in '<RegexURLResolver <RegexURLPattern list> (admin:admin) ^admin/>'
[2016-11-01 12:00:13] DEBUG [django.template:927] Exception while resolving variable 'name' in template 'unknown'.
Traceback (most recent call last):
  File "D:\pydev\marketsoft\ve_market\lib\site-packages\django\core\handlers\base.py", line 134, in get_response
    resolver_match = resolver.resolve(request.path_info)
  File "D:\pydev\marketsoft\ve_market\lib\site-packages\django\core\urlresolvers.py", line 404, in resolve
    raise Resolver404({'tried': tried, 'path': new_path})
django.core.urlresolvers.Resolver404: {'tried': [[<RegexURLResolver <RegexURLPattern list> (admin:admin) ^admin/>], [<RegexURLResolver <module 'django.contrib.admindocs.urls' from 'D:\\pydev\\marketsoft\\ve_market\\lib\\site-packages\\django\\contrib\\admindocs\\urls.py'> (None:None) ^admin/doc/>], [<RegexURLResolver <module 'rest_framework.urls' from 'D:\\pydev\\marketsoft\\ve_market\\lib\\site-packages\\rest_framework\\urls.py'> (rest_framework:rest_framework) ^api-auth/>], [<RegexURLResolver <module 'oauth2_provider.urls' from 'D:\\pydev\\marketsoft\\ve_market\\lib\\site-packages\\oauth2_provider\\urls.py'> (None:oauth2_provider) ^o/>], [<RegexURLResolver <module 'ioteca_service_apps.auths_api.urls' from 'D:\\pydev\\marketsoft\\ioteca_service\\ioteca_service_apps\\auths_api\\urls.py'> (None:None) ^api/auths/>], [<RegexURLResolver <module 'ioteca_service_apps.catalogo_api.urls' from 'D:\\pydev\\marketsoft\\ioteca_service\\ioteca_service_apps\\catalogo_api\\urls.py'> (None:None) ^api/catalogo/>]], 'path': ''}

During handling of the above exception, another exception occurred:

Traceback (most recent call last):
  File "D:\pydev\marketsoft\ve_market\lib\site-packages\django\template\base.py", line 883, in _resolve_lookup
    current = current[bit]
TypeError: 'RegexURLResolver' object is not subscriptable

During handling of the above exception, another exception occurred:

Traceback (most recent call last):
  File "D:\pydev\marketsoft\ve_market\lib\site-packages\django\template\base.py", line 891, in _resolve_lookup
    current = getattr(current, bit)
AttributeError: 'RegexURLResolver' object has no attribute 'name'

During handling of the above exception, another exception occurred:

Traceback (most recent call last):
  File "D:\pydev\marketsoft\ve_market\lib\site-packages\django\template\base.py", line 898, in _resolve_lookup
    current = current[int(bit)]
ValueError: invalid literal for int() with base 10: 'name'

During handling of the above exception, another exception occurred:

Traceback (most recent call last):
  File "D:\pydev\marketsoft\ve_market\lib\site-packages\django\template\base.py", line 905, in _resolve_lookup
    (bit, current))  # missing attribute
django.template.base.VariableDoesNotExist: Failed lookup for key [name] in "<RegexURLResolver <module 'django.contrib.admindocs.urls' from 'D:\\\\pydev\\\\marketsoft\\\\ve_market\\\\lib\\\\site-packages\\\\django\\\\contrib\\\\admindocs\\\\urls.py'> (None:None) ^admin/doc/>"
[2016-11-01 12:00:13] DEBUG [django.template:927] Exception while resolving variable 'name' in template 'unknown'.
Traceback (most recent call last):
  File "D:\pydev\marketsoft\ve_market\lib\site-packages\django\core\handlers\base.py", line 134, in get_response
    resolver_match = resolver.resolve(request.path_info)
  File "D:\pydev\marketsoft\ve_market\lib\site-packages\django\core\urlresolvers.py", line 404, in resolve
    raise Resolver404({'tried': tried, 'path': new_path})
django.core.urlresolvers.Resolver404: {'tried': [[<RegexURLResolver <RegexURLPattern list> (admin:admin) ^admin/>], [<RegexURLResolver <module 'django.contrib.admindocs.urls' from 'D:\\pydev\\marketsoft\\ve_market\\lib\\site-packages\\django\\contrib\\admindocs\\urls.py'> (None:None) ^admin/doc/>], [<RegexURLResolver <module 'rest_framework.urls' from 'D:\\pydev\\marketsoft\\ve_market\\lib\\site-packages\\rest_framework\\urls.py'> (rest_framework:rest_framework) ^api-auth/>], [<RegexURLResolver <module 'oauth2_provider.urls' from 'D:\\pydev\\marketsoft\\ve_market\\lib\\site-packages\\oauth2_provider\\urls.py'> (None:oauth2_provider) ^o/>], [<RegexURLResolver <module 'ioteca_service_apps.auths_api.urls' from 'D:\\pydev\\marketsoft\\ioteca_service\\ioteca_service_apps\\auths_api\\urls.py'> (None:None) ^api/auths/>], [<RegexURLResolver <module 'ioteca_service_apps.catalogo_api.urls' from 'D:\\pydev\\marketsoft\\ioteca_service\\ioteca_service_apps\\catalogo_api\\urls.py'> (None:None) ^api/catalogo/>]], 'path': ''}

During handling of the above exception, another exception occurred:

Traceback (most recent call last):
  File "D:\pydev\marketsoft\ve_market\lib\site-packages\django\template\base.py", line 883, in _resolve_lookup
    current = current[bit]
TypeError: 'RegexURLResolver' object is not subscriptable

During handling of the above exception, another exception occurred:

Traceback (most recent call last):
  File "D:\pydev\marketsoft\ve_market\lib\site-packages\django\template\base.py", line 891, in _resolve_lookup
    current = getattr(current, bit)
AttributeError: 'RegexURLResolver' object has no attribute 'name'

During handling of the above exception, another exception occurred:

Traceback (most recent call last):
  File "D:\pydev\marketsoft\ve_market\lib\site-packages\django\template\base.py", line 898, in _resolve_lookup
    current = current[int(bit)]
ValueError: invalid literal for int() with base 10: 'name'

During handling of the above exception, another exception occurred:

Traceback (most recent call last):
  File "D:\pydev\marketsoft\ve_market\lib\site-packages\django\template\base.py", line 905, in _resolve_lookup
    (bit, current))  # missing attribute
django.template.base.VariableDoesNotExist: Failed lookup for key [name] in "<RegexURLResolver <module 'rest_framework.urls' from 'D:\\\\pydev\\\\marketsoft\\\\ve_market\\\\lib\\\\site-packages\\\\rest_framework\\\\urls.py'> (rest_framework:rest_framework) ^api-auth/>"
[2016-11-01 12:00:13] DEBUG [django.template:927] Exception while resolving variable 'name' in template 'unknown'.
Traceback (most recent call last):
  File "D:\pydev\marketsoft\ve_market\lib\site-packages\django\core\handlers\base.py", line 134, in get_response
    resolver_match = resolver.resolve(request.path_info)
  File "D:\pydev\marketsoft\ve_market\lib\site-packages\django\core\urlresolvers.py", line 404, in resolve
    raise Resolver404({'tried': tried, 'path': new_path})
django.core.urlresolvers.Resolver404: {'tried': [[<RegexURLResolver <RegexURLPattern list> (admin:admin) ^admin/>], [<RegexURLResolver <module 'django.contrib.admindocs.urls' from 'D:\\pydev\\marketsoft\\ve_market\\lib\\site-packages\\django\\contrib\\admindocs\\urls.py'> (None:None) ^admin/doc/>], [<RegexURLResolver <module 'rest_framework.urls' from 'D:\\pydev\\marketsoft\\ve_market\\lib\\site-packages\\rest_framework\\urls.py'> (rest_framework:rest_framework) ^api-auth/>], [<RegexURLResolver <module 'oauth2_provider.urls' from 'D:\\pydev\\marketsoft\\ve_market\\lib\\site-packages\\oauth2_provider\\urls.py'> (None:oauth2_provider) ^o/>], [<RegexURLResolver <module 'ioteca_service_apps.auths_api.urls' from 'D:\\pydev\\marketsoft\\ioteca_service\\ioteca_service_apps\\auths_api\\urls.py'> (None:None) ^api/auths/>], [<RegexURLResolver <module 'ioteca_service_apps.catalogo_api.urls' from 'D:\\pydev\\marketsoft\\ioteca_service\\ioteca_service_apps\\catalogo_api\\urls.py'> (None:None) ^api/catalogo/>]], 'path': ''}

During handling of the above exception, another exception occurred:

Traceback (most recent call last):
  File "D:\pydev\marketsoft\ve_market\lib\site-packages\django\template\base.py", line 883, in _resolve_lookup
    current = current[bit]
TypeError: 'RegexURLResolver' object is not subscriptable

During handling of the above exception, another exception occurred:

Traceback (most recent call last):
  File "D:\pydev\marketsoft\ve_market\lib\site-packages\django\template\base.py", line 891, in _resolve_lookup
    current = getattr(current, bit)
AttributeError: 'RegexURLResolver' object has no attribute 'name'

During handling of the above exception, another exception occurred:

Traceback (most recent call last):
  File "D:\pydev\marketsoft\ve_market\lib\site-packages\django\template\base.py", line 898, in _resolve_lookup
    current = current[int(bit)]
ValueError: invalid literal for int() with base 10: 'name'

During handling of the above exception, another exception occurred:

Traceback (most recent call last):
  File "D:\pydev\marketsoft\ve_market\lib\site-packages\django\template\base.py", line 905, in _resolve_lookup
    (bit, current))  # missing attribute
django.template.base.VariableDoesNotExist: Failed lookup for key [name] in "<RegexURLResolver <module 'oauth2_provider.urls' from 'D:\\\\pydev\\\\marketsoft\\\\ve_market\\\\lib\\\\site-packages\\\\oauth2_provider\\\\urls.py'> (None:oauth2_provider) ^o/>"
[2016-11-01 12:00:13] DEBUG [django.template:927] Exception while resolving variable 'name' in template 'unknown'.
Traceback (most recent call last):
  File "D:\pydev\marketsoft\ve_market\lib\site-packages\django\core\handlers\base.py", line 134, in get_response
    resolver_match = resolver.resolve(request.path_info)
  File "D:\pydev\marketsoft\ve_market\lib\site-packages\django\core\urlresolvers.py", line 404, in resolve
    raise Resolver404({'tried': tried, 'path': new_path})
django.core.urlresolvers.Resolver404: {'tried': [[<RegexURLResolver <RegexURLPattern list> (admin:admin) ^admin/>], [<RegexURLResolver <module 'django.contrib.admindocs.urls' from 'D:\\pydev\\marketsoft\\ve_market\\lib\\site-packages\\django\\contrib\\admindocs\\urls.py'> (None:None) ^admin/doc/>], [<RegexURLResolver <module 'rest_framework.urls' from 'D:\\pydev\\marketsoft\\ve_market\\lib\\site-packages\\rest_framework\\urls.py'> (rest_framework:rest_framework) ^api-auth/>], [<RegexURLResolver <module 'oauth2_provider.urls' from 'D:\\pydev\\marketsoft\\ve_market\\lib\\site-packages\\oauth2_provider\\urls.py'> (None:oauth2_provider) ^o/>], [<RegexURLResolver <module 'ioteca_service_apps.auths_api.urls' from 'D:\\pydev\\marketsoft\\ioteca_service\\ioteca_service_apps\\auths_api\\urls.py'> (None:None) ^api/auths/>], [<RegexURLResolver <module 'ioteca_service_apps.catalogo_api.urls' from 'D:\\pydev\\marketsoft\\ioteca_service\\ioteca_service_apps\\catalogo_api\\urls.py'> (None:None) ^api/catalogo/>]], 'path': ''}

During handling of the above exception, another exception occurred:

Traceback (most recent call last):
  File "D:\pydev\marketsoft\ve_market\lib\site-packages\django\template\base.py", line 883, in _resolve_lookup
    current = current[bit]
TypeError: 'RegexURLResolver' object is not subscriptable

During handling of the above exception, another exception occurred:

Traceback (most recent call last):
  File "D:\pydev\marketsoft\ve_market\lib\site-packages\django\template\base.py", line 891, in _resolve_lookup
    current = getattr(current, bit)
AttributeError: 'RegexURLResolver' object has no attribute 'name'

During handling of the above exception, another exception occurred:

Traceback (most recent call last):
  File "D:\pydev\marketsoft\ve_market\lib\site-packages\django\template\base.py", line 898, in _resolve_lookup
    current = current[int(bit)]
ValueError: invalid literal for int() with base 10: 'name'

During handling of the above exception, another exception occurred:

Traceback (most recent call last):
  File "D:\pydev\marketsoft\ve_market\lib\site-packages\django\template\base.py", line 905, in _resolve_lookup
    (bit, current))  # missing attribute
django.template.base.VariableDoesNotExist: Failed lookup for key [name] in "<RegexURLResolver <module 'ioteca_service_apps.auths_api.urls' from 'D:\\\\pydev\\\\marketsoft\\\\ioteca_service\\\\ioteca_service_apps\\\\auths_api\\\\urls.py'> (None:None) ^api/auths/>"
[2016-11-01 12:00:13] DEBUG [django.template:927] Exception while resolving variable 'name' in template 'unknown'.
Traceback (most recent call last):
  File "D:\pydev\marketsoft\ve_market\lib\site-packages\django\core\handlers\base.py", line 134, in get_response
    resolver_match = resolver.resolve(request.path_info)
  File "D:\pydev\marketsoft\ve_market\lib\site-packages\django\core\urlresolvers.py", line 404, in resolve
    raise Resolver404({'tried': tried, 'path': new_path})
django.core.urlresolvers.Resolver404: {'tried': [[<RegexURLResolver <RegexURLPattern list> (admin:admin) ^admin/>], [<RegexURLResolver <module 'django.contrib.admindocs.urls' from 'D:\\pydev\\marketsoft\\ve_market\\lib\\site-packages\\django\\contrib\\admindocs\\urls.py'> (None:None) ^admin/doc/>], [<RegexURLResolver <module 'rest_framework.urls' from 'D:\\pydev\\marketsoft\\ve_market\\lib\\site-packages\\rest_framework\\urls.py'> (rest_framework:rest_framework) ^api-auth/>], [<RegexURLResolver <module 'oauth2_provider.urls' from 'D:\\pydev\\marketsoft\\ve_market\\lib\\site-packages\\oauth2_provider\\urls.py'> (None:oauth2_provider) ^o/>], [<RegexURLResolver <module 'ioteca_service_apps.auths_api.urls' from 'D:\\pydev\\marketsoft\\ioteca_service\\ioteca_service_apps\\auths_api\\urls.py'> (None:None) ^api/auths/>], [<RegexURLResolver <module 'ioteca_service_apps.catalogo_api.urls' from 'D:\\pydev\\marketsoft\\ioteca_service\\ioteca_service_apps\\catalogo_api\\urls.py'> (None:None) ^api/catalogo/>]], 'path': ''}

During handling of the above exception, another exception occurred:

Traceback (most recent call last):
  File "D:\pydev\marketsoft\ve_market\lib\site-packages\django\template\base.py", line 883, in _resolve_lookup
    current = current[bit]
TypeError: 'RegexURLResolver' object is not subscriptable

During handling of the above exception, another exception occurred:

Traceback (most recent call last):
  File "D:\pydev\marketsoft\ve_market\lib\site-packages\django\template\base.py", line 891, in _resolve_lookup
    current = getattr(current, bit)
AttributeError: 'RegexURLResolver' object has no attribute 'name'

During handling of the above exception, another exception occurred:

Traceback (most recent call last):
  File "D:\pydev\marketsoft\ve_market\lib\site-packages\django\template\base.py", line 898, in _resolve_lookup
    current = current[int(bit)]
ValueError: invalid literal for int() with base 10: 'name'

During handling of the above exception, another exception occurred:

Traceback (most recent call last):
  File "D:\pydev\marketsoft\ve_market\lib\site-packages\django\template\base.py", line 905, in _resolve_lookup
    (bit, current))  # missing attribute
django.template.base.VariableDoesNotExist: Failed lookup for key [name] in "<RegexURLResolver <module 'ioteca_service_apps.catalogo_api.urls' from 'D:\\\\pydev\\\\marketsoft\\\\ioteca_service\\\\ioteca_service_apps\\\\catalogo_api\\\\urls.py'> (None:None) ^api/catalogo/>"
[2016-11-01 12:00:13] WARNING [django.request:182] Not Found: /favicon.ico
[2016-11-01 12:00:13] DEBUG [django.template:927] Exception while resolving variable 'name' in template 'unknown'.
Traceback (most recent call last):
  File "D:\pydev\marketsoft\ve_market\lib\site-packages\django\core\handlers\base.py", line 134, in get_response
    resolver_match = resolver.resolve(request.path_info)
  File "D:\pydev\marketsoft\ve_market\lib\site-packages\django\core\urlresolvers.py", line 404, in resolve
    raise Resolver404({'tried': tried, 'path': new_path})
django.core.urlresolvers.Resolver404: {'tried': [[<RegexURLResolver <RegexURLPattern list> (admin:admin) ^admin/>], [<RegexURLResolver <module 'django.contrib.admindocs.urls' from 'D:\\pydev\\marketsoft\\ve_market\\lib\\site-packages\\django\\contrib\\admindocs\\urls.py'> (None:None) ^admin/doc/>], [<RegexURLResolver <module 'rest_framework.urls' from 'D:\\pydev\\marketsoft\\ve_market\\lib\\site-packages\\rest_framework\\urls.py'> (rest_framework:rest_framework) ^api-auth/>], [<RegexURLResolver <module 'oauth2_provider.urls' from 'D:\\pydev\\marketsoft\\ve_market\\lib\\site-packages\\oauth2_provider\\urls.py'> (None:oauth2_provider) ^o/>], [<RegexURLResolver <module 'ioteca_service_apps.auths_api.urls' from 'D:\\pydev\\marketsoft\\ioteca_service\\ioteca_service_apps\\auths_api\\urls.py'> (None:None) ^api/auths/>], [<RegexURLResolver <module 'ioteca_service_apps.catalogo_api.urls' from 'D:\\pydev\\marketsoft\\ioteca_service\\ioteca_service_apps\\catalogo_api\\urls.py'> (None:None) ^api/catalogo/>]], 'path': 'favicon.ico'}

During handling of the above exception, another exception occurred:

Traceback (most recent call last):
  File "D:\pydev\marketsoft\ve_market\lib\site-packages\django\template\base.py", line 883, in _resolve_lookup
    current = current[bit]
TypeError: 'RegexURLResolver' object is not subscriptable

During handling of the above exception, another exception occurred:

Traceback (most recent call last):
  File "D:\pydev\marketsoft\ve_market\lib\site-packages\django\template\base.py", line 891, in _resolve_lookup
    current = getattr(current, bit)
AttributeError: 'RegexURLResolver' object has no attribute 'name'

During handling of the above exception, another exception occurred:

Traceback (most recent call last):
  File "D:\pydev\marketsoft\ve_market\lib\site-packages\django\template\base.py", line 898, in _resolve_lookup
    current = current[int(bit)]
ValueError: invalid literal for int() with base 10: 'name'

During handling of the above exception, another exception occurred:

Traceback (most recent call last):
  File "D:\pydev\marketsoft\ve_market\lib\site-packages\django\template\base.py", line 905, in _resolve_lookup
    (bit, current))  # missing attribute
django.template.base.VariableDoesNotExist: Failed lookup for key [name] in '<RegexURLResolver <RegexURLPattern list> (admin:admin) ^admin/>'
[2016-11-01 12:00:13] DEBUG [django.template:927] Exception while resolving variable 'name' in template 'unknown'.
Traceback (most recent call last):
  File "D:\pydev\marketsoft\ve_market\lib\site-packages\django\core\handlers\base.py", line 134, in get_response
    resolver_match = resolver.resolve(request.path_info)
  File "D:\pydev\marketsoft\ve_market\lib\site-packages\django\core\urlresolvers.py", line 404, in resolve
    raise Resolver404({'tried': tried, 'path': new_path})
django.core.urlresolvers.Resolver404: {'tried': [[<RegexURLResolver <RegexURLPattern list> (admin:admin) ^admin/>], [<RegexURLResolver <module 'django.contrib.admindocs.urls' from 'D:\\pydev\\marketsoft\\ve_market\\lib\\site-packages\\django\\contrib\\admindocs\\urls.py'> (None:None) ^admin/doc/>], [<RegexURLResolver <module 'rest_framework.urls' from 'D:\\pydev\\marketsoft\\ve_market\\lib\\site-packages\\rest_framework\\urls.py'> (rest_framework:rest_framework) ^api-auth/>], [<RegexURLResolver <module 'oauth2_provider.urls' from 'D:\\pydev\\marketsoft\\ve_market\\lib\\site-packages\\oauth2_provider\\urls.py'> (None:oauth2_provider) ^o/>], [<RegexURLResolver <module 'ioteca_service_apps.auths_api.urls' from 'D:\\pydev\\marketsoft\\ioteca_service\\ioteca_service_apps\\auths_api\\urls.py'> (None:None) ^api/auths/>], [<RegexURLResolver <module 'ioteca_service_apps.catalogo_api.urls' from 'D:\\pydev\\marketsoft\\ioteca_service\\ioteca_service_apps\\catalogo_api\\urls.py'> (None:None) ^api/catalogo/>]], 'path': 'favicon.ico'}

During handling of the above exception, another exception occurred:

Traceback (most recent call last):
  File "D:\pydev\marketsoft\ve_market\lib\site-packages\django\template\base.py", line 883, in _resolve_lookup
    current = current[bit]
TypeError: 'RegexURLResolver' object is not subscriptable

During handling of the above exception, another exception occurred:

Traceback (most recent call last):
  File "D:\pydev\marketsoft\ve_market\lib\site-packages\django\template\base.py", line 891, in _resolve_lookup
    current = getattr(current, bit)
AttributeError: 'RegexURLResolver' object has no attribute 'name'

During handling of the above exception, another exception occurred:

Traceback (most recent call last):
  File "D:\pydev\marketsoft\ve_market\lib\site-packages\django\template\base.py", line 898, in _resolve_lookup
    current = current[int(bit)]
ValueError: invalid literal for int() with base 10: 'name'

During handling of the above exception, another exception occurred:

Traceback (most recent call last):
  File "D:\pydev\marketsoft\ve_market\lib\site-packages\django\template\base.py", line 905, in _resolve_lookup
    (bit, current))  # missing attribute
django.template.base.VariableDoesNotExist: Failed lookup for key [name] in "<RegexURLResolver <module 'django.contrib.admindocs.urls' from 'D:\\\\pydev\\\\marketsoft\\\\ve_market\\\\lib\\\\site-packages\\\\django\\\\contrib\\\\admindocs\\\\urls.py'> (None:None) ^admin/doc/>"
[2016-11-01 12:00:13] DEBUG [django.template:927] Exception while resolving variable 'name' in template 'unknown'.
Traceback (most recent call last):
  File "D:\pydev\marketsoft\ve_market\lib\site-packages\django\core\handlers\base.py", line 134, in get_response
    resolver_match = resolver.resolve(request.path_info)
  File "D:\pydev\marketsoft\ve_market\lib\site-packages\django\core\urlresolvers.py", line 404, in resolve
    raise Resolver404({'tried': tried, 'path': new_path})
django.core.urlresolvers.Resolver404: {'tried': [[<RegexURLResolver <RegexURLPattern list> (admin:admin) ^admin/>], [<RegexURLResolver <module 'django.contrib.admindocs.urls' from 'D:\\pydev\\marketsoft\\ve_market\\lib\\site-packages\\django\\contrib\\admindocs\\urls.py'> (None:None) ^admin/doc/>], [<RegexURLResolver <module 'rest_framework.urls' from 'D:\\pydev\\marketsoft\\ve_market\\lib\\site-packages\\rest_framework\\urls.py'> (rest_framework:rest_framework) ^api-auth/>], [<RegexURLResolver <module 'oauth2_provider.urls' from 'D:\\pydev\\marketsoft\\ve_market\\lib\\site-packages\\oauth2_provider\\urls.py'> (None:oauth2_provider) ^o/>], [<RegexURLResolver <module 'ioteca_service_apps.auths_api.urls' from 'D:\\pydev\\marketsoft\\ioteca_service\\ioteca_service_apps\\auths_api\\urls.py'> (None:None) ^api/auths/>], [<RegexURLResolver <module 'ioteca_service_apps.catalogo_api.urls' from 'D:\\pydev\\marketsoft\\ioteca_service\\ioteca_service_apps\\catalogo_api\\urls.py'> (None:None) ^api/catalogo/>]], 'path': 'favicon.ico'}

During handling of the above exception, another exception occurred:

Traceback (most recent call last):
  File "D:\pydev\marketsoft\ve_market\lib\site-packages\django\template\base.py", line 883, in _resolve_lookup
    current = current[bit]
TypeError: 'RegexURLResolver' object is not subscriptable

During handling of the above exception, another exception occurred:

Traceback (most recent call last):
  File "D:\pydev\marketsoft\ve_market\lib\site-packages\django\template\base.py", line 891, in _resolve_lookup
    current = getattr(current, bit)
AttributeError: 'RegexURLResolver' object has no attribute 'name'

During handling of the above exception, another exception occurred:

Traceback (most recent call last):
  File "D:\pydev\marketsoft\ve_market\lib\site-packages\django\template\base.py", line 898, in _resolve_lookup
    current = current[int(bit)]
ValueError: invalid literal for int() with base 10: 'name'

During handling of the above exception, another exception occurred:

Traceback (most recent call last):
  File "D:\pydev\marketsoft\ve_market\lib\site-packages\django\template\base.py", line 905, in _resolve_lookup
    (bit, current))  # missing attribute
django.template.base.VariableDoesNotExist: Failed lookup for key [name] in "<RegexURLResolver <module 'rest_framework.urls' from 'D:\\\\pydev\\\\marketsoft\\\\ve_market\\\\lib\\\\site-packages\\\\rest_framework\\\\urls.py'> (rest_framework:rest_framework) ^api-auth/>"
[2016-11-01 12:00:13] DEBUG [django.template:927] Exception while resolving variable 'name' in template 'unknown'.
Traceback (most recent call last):
  File "D:\pydev\marketsoft\ve_market\lib\site-packages\django\core\handlers\base.py", line 134, in get_response
    resolver_match = resolver.resolve(request.path_info)
  File "D:\pydev\marketsoft\ve_market\lib\site-packages\django\core\urlresolvers.py", line 404, in resolve
    raise Resolver404({'tried': tried, 'path': new_path})
django.core.urlresolvers.Resolver404: {'tried': [[<RegexURLResolver <RegexURLPattern list> (admin:admin) ^admin/>], [<RegexURLResolver <module 'django.contrib.admindocs.urls' from 'D:\\pydev\\marketsoft\\ve_market\\lib\\site-packages\\django\\contrib\\admindocs\\urls.py'> (None:None) ^admin/doc/>], [<RegexURLResolver <module 'rest_framework.urls' from 'D:\\pydev\\marketsoft\\ve_market\\lib\\site-packages\\rest_framework\\urls.py'> (rest_framework:rest_framework) ^api-auth/>], [<RegexURLResolver <module 'oauth2_provider.urls' from 'D:\\pydev\\marketsoft\\ve_market\\lib\\site-packages\\oauth2_provider\\urls.py'> (None:oauth2_provider) ^o/>], [<RegexURLResolver <module 'ioteca_service_apps.auths_api.urls' from 'D:\\pydev\\marketsoft\\ioteca_service\\ioteca_service_apps\\auths_api\\urls.py'> (None:None) ^api/auths/>], [<RegexURLResolver <module 'ioteca_service_apps.catalogo_api.urls' from 'D:\\pydev\\marketsoft\\ioteca_service\\ioteca_service_apps\\catalogo_api\\urls.py'> (None:None) ^api/catalogo/>]], 'path': 'favicon.ico'}

During handling of the above exception, another exception occurred:

Traceback (most recent call last):
  File "D:\pydev\marketsoft\ve_market\lib\site-packages\django\template\base.py", line 883, in _resolve_lookup
    current = current[bit]
TypeError: 'RegexURLResolver' object is not subscriptable

During handling of the above exception, another exception occurred:

Traceback (most recent call last):
  File "D:\pydev\marketsoft\ve_market\lib\site-packages\django\template\base.py", line 891, in _resolve_lookup
    current = getattr(current, bit)
AttributeError: 'RegexURLResolver' object has no attribute 'name'

During handling of the above exception, another exception occurred:

Traceback (most recent call last):
  File "D:\pydev\marketsoft\ve_market\lib\site-packages\django\template\base.py", line 898, in _resolve_lookup
    current = current[int(bit)]
ValueError: invalid literal for int() with base 10: 'name'

During handling of the above exception, another exception occurred:

Traceback (most recent call last):
  File "D:\pydev\marketsoft\ve_market\lib\site-packages\django\template\base.py", line 905, in _resolve_lookup
    (bit, current))  # missing attribute
django.template.base.VariableDoesNotExist: Failed lookup for key [name] in "<RegexURLResolver <module 'oauth2_provider.urls' from 'D:\\\\pydev\\\\marketsoft\\\\ve_market\\\\lib\\\\site-packages\\\\oauth2_provider\\\\urls.py'> (None:oauth2_provider) ^o/>"
[2016-11-01 12:00:13] DEBUG [django.template:927] Exception while resolving variable 'name' in template 'unknown'.
Traceback (most recent call last):
  File "D:\pydev\marketsoft\ve_market\lib\site-packages\django\core\handlers\base.py", line 134, in get_response
    resolver_match = resolver.resolve(request.path_info)
  File "D:\pydev\marketsoft\ve_market\lib\site-packages\django\core\urlresolvers.py", line 404, in resolve
    raise Resolver404({'tried': tried, 'path': new_path})
django.core.urlresolvers.Resolver404: {'tried': [[<RegexURLResolver <RegexURLPattern list> (admin:admin) ^admin/>], [<RegexURLResolver <module 'django.contrib.admindocs.urls' from 'D:\\pydev\\marketsoft\\ve_market\\lib\\site-packages\\django\\contrib\\admindocs\\urls.py'> (None:None) ^admin/doc/>], [<RegexURLResolver <module 'rest_framework.urls' from 'D:\\pydev\\marketsoft\\ve_market\\lib\\site-packages\\rest_framework\\urls.py'> (rest_framework:rest_framework) ^api-auth/>], [<RegexURLResolver <module 'oauth2_provider.urls' from 'D:\\pydev\\marketsoft\\ve_market\\lib\\site-packages\\oauth2_provider\\urls.py'> (None:oauth2_provider) ^o/>], [<RegexURLResolver <module 'ioteca_service_apps.auths_api.urls' from 'D:\\pydev\\marketsoft\\ioteca_service\\ioteca_service_apps\\auths_api\\urls.py'> (None:None) ^api/auths/>], [<RegexURLResolver <module 'ioteca_service_apps.catalogo_api.urls' from 'D:\\pydev\\marketsoft\\ioteca_service\\ioteca_service_apps\\catalogo_api\\urls.py'> (None:None) ^api/catalogo/>]], 'path': 'favicon.ico'}

During handling of the above exception, another exception occurred:

Traceback (most recent call last):
  File "D:\pydev\marketsoft\ve_market\lib\site-packages\django\template\base.py", line 883, in _resolve_lookup
    current = current[bit]
TypeError: 'RegexURLResolver' object is not subscriptable

During handling of the above exception, another exception occurred:

Traceback (most recent call last):
  File "D:\pydev\marketsoft\ve_market\lib\site-packages\django\template\base.py", line 891, in _resolve_lookup
    current = getattr(current, bit)
AttributeError: 'RegexURLResolver' object has no attribute 'name'

During handling of the above exception, another exception occurred:

Traceback (most recent call last):
  File "D:\pydev\marketsoft\ve_market\lib\site-packages\django\template\base.py", line 898, in _resolve_lookup
    current = current[int(bit)]
ValueError: invalid literal for int() with base 10: 'name'

During handling of the above exception, another exception occurred:

Traceback (most recent call last):
  File "D:\pydev\marketsoft\ve_market\lib\site-packages\django\template\base.py", line 905, in _resolve_lookup
    (bit, current))  # missing attribute
django.template.base.VariableDoesNotExist: Failed lookup for key [name] in "<RegexURLResolver <module 'ioteca_service_apps.auths_api.urls' from 'D:\\\\pydev\\\\marketsoft\\\\ioteca_service\\\\ioteca_service_apps\\\\auths_api\\\\urls.py'> (None:None) ^api/auths/>"
[2016-11-01 12:00:13] DEBUG [django.template:927] Exception while resolving variable 'name' in template 'unknown'.
Traceback (most recent call last):
  File "D:\pydev\marketsoft\ve_market\lib\site-packages\django\core\handlers\base.py", line 134, in get_response
    resolver_match = resolver.resolve(request.path_info)
  File "D:\pydev\marketsoft\ve_market\lib\site-packages\django\core\urlresolvers.py", line 404, in resolve
    raise Resolver404({'tried': tried, 'path': new_path})
django.core.urlresolvers.Resolver404: {'tried': [[<RegexURLResolver <RegexURLPattern list> (admin:admin) ^admin/>], [<RegexURLResolver <module 'django.contrib.admindocs.urls' from 'D:\\pydev\\marketsoft\\ve_market\\lib\\site-packages\\django\\contrib\\admindocs\\urls.py'> (None:None) ^admin/doc/>], [<RegexURLResolver <module 'rest_framework.urls' from 'D:\\pydev\\marketsoft\\ve_market\\lib\\site-packages\\rest_framework\\urls.py'> (rest_framework:rest_framework) ^api-auth/>], [<RegexURLResolver <module 'oauth2_provider.urls' from 'D:\\pydev\\marketsoft\\ve_market\\lib\\site-packages\\oauth2_provider\\urls.py'> (None:oauth2_provider) ^o/>], [<RegexURLResolver <module 'ioteca_service_apps.auths_api.urls' from 'D:\\pydev\\marketsoft\\ioteca_service\\ioteca_service_apps\\auths_api\\urls.py'> (None:None) ^api/auths/>], [<RegexURLResolver <module 'ioteca_service_apps.catalogo_api.urls' from 'D:\\pydev\\marketsoft\\ioteca_service\\ioteca_service_apps\\catalogo_api\\urls.py'> (None:None) ^api/catalogo/>]], 'path': 'favicon.ico'}

During handling of the above exception, another exception occurred:

Traceback (most recent call last):
  File "D:\pydev\marketsoft\ve_market\lib\site-packages\django\template\base.py", line 883, in _resolve_lookup
    current = current[bit]
TypeError: 'RegexURLResolver' object is not subscriptable

During handling of the above exception, another exception occurred:

Traceback (most recent call last):
  File "D:\pydev\marketsoft\ve_market\lib\site-packages\django\template\base.py", line 891, in _resolve_lookup
    current = getattr(current, bit)
AttributeError: 'RegexURLResolver' object has no attribute 'name'

During handling of the above exception, another exception occurred:

Traceback (most recent call last):
  File "D:\pydev\marketsoft\ve_market\lib\site-packages\django\template\base.py", line 898, in _resolve_lookup
    current = current[int(bit)]
ValueError: invalid literal for int() with base 10: 'name'

During handling of the above exception, another exception occurred:

Traceback (most recent call last):
  File "D:\pydev\marketsoft\ve_market\lib\site-packages\django\template\base.py", line 905, in _resolve_lookup
    (bit, current))  # missing attribute
django.template.base.VariableDoesNotExist: Failed lookup for key [name] in "<RegexURLResolver <module 'ioteca_service_apps.catalogo_api.urls' from 'D:\\\\pydev\\\\marketsoft\\\\ioteca_service\\\\ioteca_service_apps\\\\catalogo_api\\\\urls.py'> (None:None) ^api/catalogo/>"
[2016-11-01 12:00:13] WARNING [django.request:182] Not Found: /favicon.ico
[2016-11-01 12:00:13] DEBUG [django.template:927] Exception while resolving variable 'name' in template 'unknown'.
Traceback (most recent call last):
  File "D:\pydev\marketsoft\ve_market\lib\site-packages\django\core\handlers\base.py", line 134, in get_response
    resolver_match = resolver.resolve(request.path_info)
  File "D:\pydev\marketsoft\ve_market\lib\site-packages\django\core\urlresolvers.py", line 404, in resolve
    raise Resolver404({'tried': tried, 'path': new_path})
django.core.urlresolvers.Resolver404: {'tried': [[<RegexURLResolver <RegexURLPattern list> (admin:admin) ^admin/>], [<RegexURLResolver <module 'django.contrib.admindocs.urls' from 'D:\\pydev\\marketsoft\\ve_market\\lib\\site-packages\\django\\contrib\\admindocs\\urls.py'> (None:None) ^admin/doc/>], [<RegexURLResolver <module 'rest_framework.urls' from 'D:\\pydev\\marketsoft\\ve_market\\lib\\site-packages\\rest_framework\\urls.py'> (rest_framework:rest_framework) ^api-auth/>], [<RegexURLResolver <module 'oauth2_provider.urls' from 'D:\\pydev\\marketsoft\\ve_market\\lib\\site-packages\\oauth2_provider\\urls.py'> (None:oauth2_provider) ^o/>], [<RegexURLResolver <module 'ioteca_service_apps.auths_api.urls' from 'D:\\pydev\\marketsoft\\ioteca_service\\ioteca_service_apps\\auths_api\\urls.py'> (None:None) ^api/auths/>], [<RegexURLResolver <module 'ioteca_service_apps.catalogo_api.urls' from 'D:\\pydev\\marketsoft\\ioteca_service\\ioteca_service_apps\\catalogo_api\\urls.py'> (None:None) ^api/catalogo/>]], 'path': 'favicon.ico'}

During handling of the above exception, another exception occurred:

Traceback (most recent call last):
  File "D:\pydev\marketsoft\ve_market\lib\site-packages\django\template\base.py", line 883, in _resolve_lookup
    current = current[bit]
TypeError: 'RegexURLResolver' object is not subscriptable

During handling of the above exception, another exception occurred:

Traceback (most recent call last):
  File "D:\pydev\marketsoft\ve_market\lib\site-packages\django\template\base.py", line 891, in _resolve_lookup
    current = getattr(current, bit)
AttributeError: 'RegexURLResolver' object has no attribute 'name'

During handling of the above exception, another exception occurred:

Traceback (most recent call last):
  File "D:\pydev\marketsoft\ve_market\lib\site-packages\django\template\base.py", line 898, in _resolve_lookup
    current = current[int(bit)]
ValueError: invalid literal for int() with base 10: 'name'

During handling of the above exception, another exception occurred:

Traceback (most recent call last):
  File "D:\pydev\marketsoft\ve_market\lib\site-packages\django\template\base.py", line 905, in _resolve_lookup
    (bit, current))  # missing attribute
django.template.base.VariableDoesNotExist: Failed lookup for key [name] in '<RegexURLResolver <RegexURLPattern list> (admin:admin) ^admin/>'
[2016-11-01 12:00:13] DEBUG [django.template:927] Exception while resolving variable 'name' in template 'unknown'.
Traceback (most recent call last):
  File "D:\pydev\marketsoft\ve_market\lib\site-packages\django\core\handlers\base.py", line 134, in get_response
    resolver_match = resolver.resolve(request.path_info)
  File "D:\pydev\marketsoft\ve_market\lib\site-packages\django\core\urlresolvers.py", line 404, in resolve
    raise Resolver404({'tried': tried, 'path': new_path})
django.core.urlresolvers.Resolver404: {'tried': [[<RegexURLResolver <RegexURLPattern list> (admin:admin) ^admin/>], [<RegexURLResolver <module 'django.contrib.admindocs.urls' from 'D:\\pydev\\marketsoft\\ve_market\\lib\\site-packages\\django\\contrib\\admindocs\\urls.py'> (None:None) ^admin/doc/>], [<RegexURLResolver <module 'rest_framework.urls' from 'D:\\pydev\\marketsoft\\ve_market\\lib\\site-packages\\rest_framework\\urls.py'> (rest_framework:rest_framework) ^api-auth/>], [<RegexURLResolver <module 'oauth2_provider.urls' from 'D:\\pydev\\marketsoft\\ve_market\\lib\\site-packages\\oauth2_provider\\urls.py'> (None:oauth2_provider) ^o/>], [<RegexURLResolver <module 'ioteca_service_apps.auths_api.urls' from 'D:\\pydev\\marketsoft\\ioteca_service\\ioteca_service_apps\\auths_api\\urls.py'> (None:None) ^api/auths/>], [<RegexURLResolver <module 'ioteca_service_apps.catalogo_api.urls' from 'D:\\pydev\\marketsoft\\ioteca_service\\ioteca_service_apps\\catalogo_api\\urls.py'> (None:None) ^api/catalogo/>]], 'path': 'favicon.ico'}

During handling of the above exception, another exception occurred:

Traceback (most recent call last):
  File "D:\pydev\marketsoft\ve_market\lib\site-packages\django\template\base.py", line 883, in _resolve_lookup
    current = current[bit]
TypeError: 'RegexURLResolver' object is not subscriptable

During handling of the above exception, another exception occurred:

Traceback (most recent call last):
  File "D:\pydev\marketsoft\ve_market\lib\site-packages\django\template\base.py", line 891, in _resolve_lookup
    current = getattr(current, bit)
AttributeError: 'RegexURLResolver' object has no attribute 'name'

During handling of the above exception, another exception occurred:

Traceback (most recent call last):
  File "D:\pydev\marketsoft\ve_market\lib\site-packages\django\template\base.py", line 898, in _resolve_lookup
    current = current[int(bit)]
ValueError: invalid literal for int() with base 10: 'name'

During handling of the above exception, another exception occurred:

Traceback (most recent call last):
  File "D:\pydev\marketsoft\ve_market\lib\site-packages\django\template\base.py", line 905, in _resolve_lookup
    (bit, current))  # missing attribute
django.template.base.VariableDoesNotExist: Failed lookup for key [name] in "<RegexURLResolver <module 'django.contrib.admindocs.urls' from 'D:\\\\pydev\\\\marketsoft\\\\ve_market\\\\lib\\\\site-packages\\\\django\\\\contrib\\\\admindocs\\\\urls.py'> (None:None) ^admin/doc/>"
[2016-11-01 12:00:13] DEBUG [django.template:927] Exception while resolving variable 'name' in template 'unknown'.
Traceback (most recent call last):
  File "D:\pydev\marketsoft\ve_market\lib\site-packages\django\core\handlers\base.py", line 134, in get_response
    resolver_match = resolver.resolve(request.path_info)
  File "D:\pydev\marketsoft\ve_market\lib\site-packages\django\core\urlresolvers.py", line 404, in resolve
    raise Resolver404({'tried': tried, 'path': new_path})
django.core.urlresolvers.Resolver404: {'tried': [[<RegexURLResolver <RegexURLPattern list> (admin:admin) ^admin/>], [<RegexURLResolver <module 'django.contrib.admindocs.urls' from 'D:\\pydev\\marketsoft\\ve_market\\lib\\site-packages\\django\\contrib\\admindocs\\urls.py'> (None:None) ^admin/doc/>], [<RegexURLResolver <module 'rest_framework.urls' from 'D:\\pydev\\marketsoft\\ve_market\\lib\\site-packages\\rest_framework\\urls.py'> (rest_framework:rest_framework) ^api-auth/>], [<RegexURLResolver <module 'oauth2_provider.urls' from 'D:\\pydev\\marketsoft\\ve_market\\lib\\site-packages\\oauth2_provider\\urls.py'> (None:oauth2_provider) ^o/>], [<RegexURLResolver <module 'ioteca_service_apps.auths_api.urls' from 'D:\\pydev\\marketsoft\\ioteca_service\\ioteca_service_apps\\auths_api\\urls.py'> (None:None) ^api/auths/>], [<RegexURLResolver <module 'ioteca_service_apps.catalogo_api.urls' from 'D:\\pydev\\marketsoft\\ioteca_service\\ioteca_service_apps\\catalogo_api\\urls.py'> (None:None) ^api/catalogo/>]], 'path': 'favicon.ico'}

During handling of the above exception, another exception occurred:

Traceback (most recent call last):
  File "D:\pydev\marketsoft\ve_market\lib\site-packages\django\template\base.py", line 883, in _resolve_lookup
    current = current[bit]
TypeError: 'RegexURLResolver' object is not subscriptable

During handling of the above exception, another exception occurred:

Traceback (most recent call last):
  File "D:\pydev\marketsoft\ve_market\lib\site-packages\django\template\base.py", line 891, in _resolve_lookup
    current = getattr(current, bit)
AttributeError: 'RegexURLResolver' object has no attribute 'name'

During handling of the above exception, another exception occurred:

Traceback (most recent call last):
  File "D:\pydev\marketsoft\ve_market\lib\site-packages\django\template\base.py", line 898, in _resolve_lookup
    current = current[int(bit)]
ValueError: invalid literal for int() with base 10: 'name'

During handling of the above exception, another exception occurred:

Traceback (most recent call last):
  File "D:\pydev\marketsoft\ve_market\lib\site-packages\django\template\base.py", line 905, in _resolve_lookup
    (bit, current))  # missing attribute
django.template.base.VariableDoesNotExist: Failed lookup for key [name] in "<RegexURLResolver <module 'rest_framework.urls' from 'D:\\\\pydev\\\\marketsoft\\\\ve_market\\\\lib\\\\site-packages\\\\rest_framework\\\\urls.py'> (rest_framework:rest_framework) ^api-auth/>"
[2016-11-01 12:00:13] DEBUG [django.template:927] Exception while resolving variable 'name' in template 'unknown'.
Traceback (most recent call last):
  File "D:\pydev\marketsoft\ve_market\lib\site-packages\django\core\handlers\base.py", line 134, in get_response
    resolver_match = resolver.resolve(request.path_info)
  File "D:\pydev\marketsoft\ve_market\lib\site-packages\django\core\urlresolvers.py", line 404, in resolve
    raise Resolver404({'tried': tried, 'path': new_path})
django.core.urlresolvers.Resolver404: {'tried': [[<RegexURLResolver <RegexURLPattern list> (admin:admin) ^admin/>], [<RegexURLResolver <module 'django.contrib.admindocs.urls' from 'D:\\pydev\\marketsoft\\ve_market\\lib\\site-packages\\django\\contrib\\admindocs\\urls.py'> (None:None) ^admin/doc/>], [<RegexURLResolver <module 'rest_framework.urls' from 'D:\\pydev\\marketsoft\\ve_market\\lib\\site-packages\\rest_framework\\urls.py'> (rest_framework:rest_framework) ^api-auth/>], [<RegexURLResolver <module 'oauth2_provider.urls' from 'D:\\pydev\\marketsoft\\ve_market\\lib\\site-packages\\oauth2_provider\\urls.py'> (None:oauth2_provider) ^o/>], [<RegexURLResolver <module 'ioteca_service_apps.auths_api.urls' from 'D:\\pydev\\marketsoft\\ioteca_service\\ioteca_service_apps\\auths_api\\urls.py'> (None:None) ^api/auths/>], [<RegexURLResolver <module 'ioteca_service_apps.catalogo_api.urls' from 'D:\\pydev\\marketsoft\\ioteca_service\\ioteca_service_apps\\catalogo_api\\urls.py'> (None:None) ^api/catalogo/>]], 'path': 'favicon.ico'}

During handling of the above exception, another exception occurred:

Traceback (most recent call last):
  File "D:\pydev\marketsoft\ve_market\lib\site-packages\django\template\base.py", line 883, in _resolve_lookup
    current = current[bit]
TypeError: 'RegexURLResolver' object is not subscriptable

During handling of the above exception, another exception occurred:

Traceback (most recent call last):
  File "D:\pydev\marketsoft\ve_market\lib\site-packages\django\template\base.py", line 891, in _resolve_lookup
    current = getattr(current, bit)
AttributeError: 'RegexURLResolver' object has no attribute 'name'

During handling of the above exception, another exception occurred:

Traceback (most recent call last):
  File "D:\pydev\marketsoft\ve_market\lib\site-packages\django\template\base.py", line 898, in _resolve_lookup
    current = current[int(bit)]
ValueError: invalid literal for int() with base 10: 'name'

During handling of the above exception, another exception occurred:

Traceback (most recent call last):
  File "D:\pydev\marketsoft\ve_market\lib\site-packages\django\template\base.py", line 905, in _resolve_lookup
    (bit, current))  # missing attribute
django.template.base.VariableDoesNotExist: Failed lookup for key [name] in "<RegexURLResolver <module 'oauth2_provider.urls' from 'D:\\\\pydev\\\\marketsoft\\\\ve_market\\\\lib\\\\site-packages\\\\oauth2_provider\\\\urls.py'> (None:oauth2_provider) ^o/>"
[2016-11-01 12:00:13] DEBUG [django.template:927] Exception while resolving variable 'name' in template 'unknown'.
Traceback (most recent call last):
  File "D:\pydev\marketsoft\ve_market\lib\site-packages\django\core\handlers\base.py", line 134, in get_response
    resolver_match = resolver.resolve(request.path_info)
  File "D:\pydev\marketsoft\ve_market\lib\site-packages\django\core\urlresolvers.py", line 404, in resolve
    raise Resolver404({'tried': tried, 'path': new_path})
django.core.urlresolvers.Resolver404: {'tried': [[<RegexURLResolver <RegexURLPattern list> (admin:admin) ^admin/>], [<RegexURLResolver <module 'django.contrib.admindocs.urls' from 'D:\\pydev\\marketsoft\\ve_market\\lib\\site-packages\\django\\contrib\\admindocs\\urls.py'> (None:None) ^admin/doc/>], [<RegexURLResolver <module 'rest_framework.urls' from 'D:\\pydev\\marketsoft\\ve_market\\lib\\site-packages\\rest_framework\\urls.py'> (rest_framework:rest_framework) ^api-auth/>], [<RegexURLResolver <module 'oauth2_provider.urls' from 'D:\\pydev\\marketsoft\\ve_market\\lib\\site-packages\\oauth2_provider\\urls.py'> (None:oauth2_provider) ^o/>], [<RegexURLResolver <module 'ioteca_service_apps.auths_api.urls' from 'D:\\pydev\\marketsoft\\ioteca_service\\ioteca_service_apps\\auths_api\\urls.py'> (None:None) ^api/auths/>], [<RegexURLResolver <module 'ioteca_service_apps.catalogo_api.urls' from 'D:\\pydev\\marketsoft\\ioteca_service\\ioteca_service_apps\\catalogo_api\\urls.py'> (None:None) ^api/catalogo/>]], 'path': 'favicon.ico'}

During handling of the above exception, another exception occurred:

Traceback (most recent call last):
  File "D:\pydev\marketsoft\ve_market\lib\site-packages\django\template\base.py", line 883, in _resolve_lookup
    current = current[bit]
TypeError: 'RegexURLResolver' object is not subscriptable

During handling of the above exception, another exception occurred:

Traceback (most recent call last):
  File "D:\pydev\marketsoft\ve_market\lib\site-packages\django\template\base.py", line 891, in _resolve_lookup
    current = getattr(current, bit)
AttributeError: 'RegexURLResolver' object has no attribute 'name'

During handling of the above exception, another exception occurred:

Traceback (most recent call last):
  File "D:\pydev\marketsoft\ve_market\lib\site-packages\django\template\base.py", line 898, in _resolve_lookup
    current = current[int(bit)]
ValueError: invalid literal for int() with base 10: 'name'

During handling of the above exception, another exception occurred:

Traceback (most recent call last):
  File "D:\pydev\marketsoft\ve_market\lib\site-packages\django\template\base.py", line 905, in _resolve_lookup
    (bit, current))  # missing attribute
django.template.base.VariableDoesNotExist: Failed lookup for key [name] in "<RegexURLResolver <module 'ioteca_service_apps.auths_api.urls' from 'D:\\\\pydev\\\\marketsoft\\\\ioteca_service\\\\ioteca_service_apps\\\\auths_api\\\\urls.py'> (None:None) ^api/auths/>"
[2016-11-01 12:00:13] DEBUG [django.template:927] Exception while resolving variable 'name' in template 'unknown'.
Traceback (most recent call last):
  File "D:\pydev\marketsoft\ve_market\lib\site-packages\django\core\handlers\base.py", line 134, in get_response
    resolver_match = resolver.resolve(request.path_info)
  File "D:\pydev\marketsoft\ve_market\lib\site-packages\django\core\urlresolvers.py", line 404, in resolve
    raise Resolver404({'tried': tried, 'path': new_path})
django.core.urlresolvers.Resolver404: {'tried': [[<RegexURLResolver <RegexURLPattern list> (admin:admin) ^admin/>], [<RegexURLResolver <module 'django.contrib.admindocs.urls' from 'D:\\pydev\\marketsoft\\ve_market\\lib\\site-packages\\django\\contrib\\admindocs\\urls.py'> (None:None) ^admin/doc/>], [<RegexURLResolver <module 'rest_framework.urls' from 'D:\\pydev\\marketsoft\\ve_market\\lib\\site-packages\\rest_framework\\urls.py'> (rest_framework:rest_framework) ^api-auth/>], [<RegexURLResolver <module 'oauth2_provider.urls' from 'D:\\pydev\\marketsoft\\ve_market\\lib\\site-packages\\oauth2_provider\\urls.py'> (None:oauth2_provider) ^o/>], [<RegexURLResolver <module 'ioteca_service_apps.auths_api.urls' from 'D:\\pydev\\marketsoft\\ioteca_service\\ioteca_service_apps\\auths_api\\urls.py'> (None:None) ^api/auths/>], [<RegexURLResolver <module 'ioteca_service_apps.catalogo_api.urls' from 'D:\\pydev\\marketsoft\\ioteca_service\\ioteca_service_apps\\catalogo_api\\urls.py'> (None:None) ^api/catalogo/>]], 'path': 'favicon.ico'}

During handling of the above exception, another exception occurred:

Traceback (most recent call last):
  File "D:\pydev\marketsoft\ve_market\lib\site-packages\django\template\base.py", line 883, in _resolve_lookup
    current = current[bit]
TypeError: 'RegexURLResolver' object is not subscriptable

During handling of the above exception, another exception occurred:

Traceback (most recent call last):
  File "D:\pydev\marketsoft\ve_market\lib\site-packages\django\template\base.py", line 891, in _resolve_lookup
    current = getattr(current, bit)
AttributeError: 'RegexURLResolver' object has no attribute 'name'

During handling of the above exception, another exception occurred:

Traceback (most recent call last):
  File "D:\pydev\marketsoft\ve_market\lib\site-packages\django\template\base.py", line 898, in _resolve_lookup
    current = current[int(bit)]
ValueError: invalid literal for int() with base 10: 'name'

During handling of the above exception, another exception occurred:

Traceback (most recent call last):
  File "D:\pydev\marketsoft\ve_market\lib\site-packages\django\template\base.py", line 905, in _resolve_lookup
    (bit, current))  # missing attribute
django.template.base.VariableDoesNotExist: Failed lookup for key [name] in "<RegexURLResolver <module 'ioteca_service_apps.catalogo_api.urls' from 'D:\\\\pydev\\\\marketsoft\\\\ioteca_service\\\\ioteca_service_apps\\\\catalogo_api\\\\urls.py'> (None:None) ^api/catalogo/>"
[2016-11-01 12:00:20] DEBUG [django.db.backends:89] (0.002) SELECT "django_session"."session_key", "django_session"."session_data", "django_session"."expire_date" FROM "django_session" WHERE ("django_session"."expire_date" > '2016-11-01 17:00:20.011839' AND "django_session"."session_key" = 'gtw0v45oztxiziavd0vcwh57etmeavi6'); args=('2016-11-01 17:00:20.011839', 'gtw0v45oztxiziavd0vcwh57etmeavi6')
[2016-11-01 12:00:20] DEBUG [django.db.backends:89] (0.001) SELECT "auths_user"."password", "auths_user"."last_login", "auths_user"."is_superuser", "auths_user"."username", "auths_user"."first_name", "auths_user"."last_name", "auths_user"."email", "auths_user"."is_staff", "auths_user"."is_active", "auths_user"."date_joined", "auths_user"."id", "auths_user"."last_hierarchy_id", "auths_user"."last_module_id", "auths_user"."person_id", "auths_user"."updated_at", "auths_user"."registered_by" FROM "auths_user" WHERE "auths_user"."id" = '4c7e4779b6bd47198afbd9e574b13d0a'; args=('4c7e4779b6bd47198afbd9e574b13d0a',)
[2016-11-01 12:00:20] DEBUG [django.template:927] Exception while resolving variable 'is_popup' in template 'admin/index.html'.
Traceback (most recent call last):
  File "D:\pydev\marketsoft\ve_market\lib\site-packages\django\template\base.py", line 883, in _resolve_lookup
    current = current[bit]
  File "D:\pydev\marketsoft\ve_market\lib\site-packages\django\template\context.py", line 77, in __getitem__
    raise KeyError(key)
KeyError: 'is_popup'

During handling of the above exception, another exception occurred:

Traceback (most recent call last):
  File "D:\pydev\marketsoft\ve_market\lib\site-packages\django\template\base.py", line 889, in _resolve_lookup
    if isinstance(current, BaseContext) and getattr(type(current), bit):
AttributeError: type object 'RequestContext' has no attribute 'is_popup'

During handling of the above exception, another exception occurred:

Traceback (most recent call last):
  File "D:\pydev\marketsoft\ve_market\lib\site-packages\django\template\base.py", line 898, in _resolve_lookup
    current = current[int(bit)]
ValueError: invalid literal for int() with base 10: 'is_popup'

During handling of the above exception, another exception occurred:

Traceback (most recent call last):
  File "D:\pydev\marketsoft\ve_market\lib\site-packages\django\template\base.py", line 905, in _resolve_lookup
    (bit, current))  # missing attribute
django.template.base.VariableDoesNotExist: Failed lookup for key [is_popup] in "[{'True': True, 'False': False, 'None': None}, {'user': <SimpleLazyObject: <User: admin>>, 'csrf_token': <SimpleLazyObject: <function csrf.<locals>._get_val at 0x04542C00>>, 'DEFAULT_MESSAGE_LEVELS': {'ERROR': 40, 'DEBUG': 10, 'SUCCESS': 25, 'INFO': 20, 'WARNING': 30}, 'request': <WSGIRequest: GET '/admin/'>, 'perms': <django.contrib.auth.context_processors.PermWrapper object at 0x0085B2D0>, 'messages': <django.contrib.messages.storage.fallback.FallbackStorage object at 0x0451EDD0>}, {}, {'has_permission': True, 'LANGUAGE_BIDI': False, 'site_header': <django.utils.functional.lazy.<locals>.__proxy__ object at 0x03766D30>, 'site_url': '/', 'app_list': [{'has_module_perms': True, 'name': <django.utils.functional.lazy.<locals>.__proxy__ object at 0x03772290>, 'app_url': '/admin/auth/', 'app_label': 'auth', 'models': [{'object_name': 'Group', 'add_url': '/admin/auth/group/add/', 'name': <django.utils.functional.lazy.<locals>.__proxy__ object at 0x00837450>, 'perms': {'change': True, 'add': True, 'delete': True}, 'admin_url': '/admin/auth/group/'}, {'object_name': 'Permission', 'add_url': '/admin/auth/permission/add/', 'name': <django.utils.functional.lazy.<locals>.__proxy__ object at 0x00837470>, 'perms': {'change': True, 'add': True, 'delete': True}, 'admin_url': '/admin/auth/permission/'}]}, {'has_module_perms': True, 'name': 'Auths', 'app_url': '/admin/auths/', 'app_label': 'auths', 'models': [{'object_name': 'HierarchyType', 'add_url': '/admin/auths/hierarchytype/add/', 'name': <django.utils.functional.lazy.<locals>.__proxy__ object at 0x0451E950>, 'perms': {'change': True, 'add': True, 'delete': True}, 'admin_url': '/admin/auths/hierarchytype/'}, {'object_name': 'Hierarchy', 'add_url': '/admin/auths/hierarchy/add/', 'name': <django.utils.functional.lazy.<locals>.__proxy__ object at 0x008373B0>, 'perms': {'change': True, 'add': True, 'delete': True}, 'admin_url': '/admin/auths/hierarchy/'}, {'object_name': 'Menu', 'add_url': '/admin/auths/menu/add/', 'name': <django.utils.functional.lazy.<locals>.__proxy__ object at 0x00837430>, 'perms': {'change': True, 'add': True, 'delete': True}, 'admin_url': '/admin/auths/menu/'}, {'object_name': 'Person', 'add_url': '/admin/auths/person/add/', 'name': <django.utils.functional.lazy.<locals>.__proxy__ object at 0x0454CFD0>, 'perms': {'change': True, 'add': True, 'delete': True}, 'admin_url': '/admin/auths/person/'}, {'object_name': 'UserHierarchyGroup', 'add_url': '/admin/auths/userhierarchygroup/add/', 'name': <django.utils.functional.lazy.<locals>.__proxy__ object at 0x008374F0>, 'perms': {'change': True, 'add': True, 'delete': True}, 'admin_url': '/admin/auths/userhierarchygroup/'}, {'object_name': 'UserHierarchyPermission', 'add_url': '/admin/auths/userhierarchypermission/add/', 'name': <django.utils.functional.lazy.<locals>.__proxy__ object at 0x008374D0>, 'perms': {'change': True, 'add': True, 'delete': True}, 'admin_url': '/admin/auths/userhierarchypermission/'}, {'object_name': 'User', 'add_url': '/admin/auths/user/add/', 'name': <django.utils.functional.lazy.<locals>.__proxy__ object at 0x008373D0>, 'perms': {'change': True, 'add': True, 'delete': True}, 'admin_url': '/admin/auths/user/'}]}, {'has_module_perms': True, 'name': 'Catalogo', 'app_url': '/admin/catalogo/', 'app_label': 'catalogo', 'models': [{'object_name': 'Cabecera', 'add_url': '/admin/catalogo/cabecera/add/', 'name': <django.utils.functional.lazy.<locals>.__proxy__ object at 0x00837390>, 'perms': {'change': True, 'add': True, 'delete': True}, 'admin_url': '/admin/catalogo/cabecera/'}, {'object_name': 'Cliente', 'add_url': '/admin/catalogo/cliente/add/', 'name': 'Clientes', 'perms': {'change': True, 'add': True, 'delete': True}, 'admin_url': '/admin/catalogo/cliente/'}, {'object_name': 'Distribuidor', 'add_url': '/admin/catalogo/distribuidor/add/', 'name': <django.utils.functional.lazy.<locals>.__proxy__ object at 0x008373F0>, 'perms': {'change': True, 'add': True, 'delete': True}, 'admin_url': '/admin/catalogo/distribuidor/'}, {'object_name': 'Empresa', 'add_url': '/admin/catalogo/empresa/add/', 'name': <django.utils.functional.lazy.<locals>.__proxy__ object at 0x0454CF70>, 'perms': {'change': True, 'add': True, 'delete': True}, 'admin_url': '/admin/catalogo/empresa/'}, {'object_name': 'Presentacion', 'add_url': '/admin/catalogo/presentacion/add/', 'name': <django.utils.functional.lazy.<locals>.__proxy__ object at 0x00837490>, 'perms': {'change': True, 'add': True, 'delete': True}, 'admin_url': '/admin/catalogo/presentacion/'}, {'object_name': 'Producto', 'add_url': '/admin/catalogo/producto/add/', 'name': <django.utils.functional.lazy.<locals>.__proxy__ object at 0x00837530>, 'perms': {'change': True, 'add': True, 'delete': True}, 'admin_url': '/admin/catalogo/producto/'}]}, {'has_module_perms': True, 'name': <django.utils.functional.lazy.<locals>.__proxy__ object at 0x037722F0>, 'app_url': '/admin/contenttypes/', 'app_label': 'contenttypes', 'models': [{'object_name': 'ContentType', 'add_url': '/admin/contenttypes/contenttype/add/', 'name': <django.utils.functional.lazy.<locals>.__proxy__ object at 0x0451E550>, 'perms': {'change': True, 'add': True, 'delete': True}, 'admin_url': '/admin/contenttypes/contenttype/'}]}, {'has_module_perms': True, 'name': 'Django OAuth Toolkit', 'app_url': '/admin/oauth2_provider/', 'app_label': 'oauth2_provider', 'models': [{'object_name': 'AccessToken', 'add_url': '/admin/oauth2_provider/accesstoken/add/', 'name': <django.utils.functional.lazy.<locals>.__proxy__ object at 0x00823DD0>, 'perms': {'change': True, 'add': True, 'delete': True}, 'admin_url': '/admin/oauth2_provider/accesstoken/'}, {'object_name': 'Application', 'add_url': '/admin/oauth2_provider/application/add/', 'name': <django.utils.functional.lazy.<locals>.__proxy__ object at 0x008374B0>, 'perms': {'change': True, 'add': True, 'delete': True}, 'admin_url': '/admin/oauth2_provider/application/'}, {'object_name': 'Grant', 'add_url': '/admin/oauth2_provider/grant/add/', 'name': <django.utils.functional.lazy.<locals>.__proxy__ object at 0x00837410>, 'perms': {'change': True, 'add': True, 'delete': True}, 'admin_url': '/admin/oauth2_provider/grant/'}, {'object_name': 'RefreshToken', 'add_url': '/admin/oauth2_provider/refreshtoken/add/', 'name': <django.utils.functional.lazy.<locals>.__proxy__ object at 0x00837550>, 'perms': {'change': True, 'add': True, 'delete': True}, 'admin_url': '/admin/oauth2_provider/refreshtoken/'}]}], 'site_title': <django.utils.functional.lazy.<locals>.__proxy__ object at 0x03766C70>, 'title': <django.utils.functional.lazy.<locals>.__proxy__ object at 0x03766D70>, 'LANGUAGE_CODE': 'en-us', 'available_apps': [{'has_module_perms': True, 'name': <django.utils.functional.lazy.<locals>.__proxy__ object at 0x03772290>, 'app_url': '/admin/auth/', 'app_label': 'auth', 'models': [{'object_name': 'Group', 'add_url': '/admin/auth/group/add/', 'name': <django.utils.functional.lazy.<locals>.__proxy__ object at 0x008378B0>, 'perms': {'change': True, 'add': True, 'delete': True}, 'admin_url': '/admin/auth/group/'}, {'object_name': 'Permission', 'add_url': '/admin/auth/permission/add/', 'name': <django.utils.functional.lazy.<locals>.__proxy__ object at 0x008377D0>, 'perms': {'change': True, 'add': True, 'delete': True}, 'admin_url': '/admin/auth/permission/'}]}, {'has_module_perms': True, 'name': 'Auths', 'app_url': '/admin/auths/', 'app_label': 'auths', 'models': [{'object_name': 'HierarchyType', 'add_url': '/admin/auths/hierarchytype/add/', 'name': <django.utils.functional.lazy.<locals>.__proxy__ object at 0x008375B0>, 'perms': {'change': True, 'add': True, 'delete': True}, 'admin_url': '/admin/auths/hierarchytype/'}, {'object_name': 'Hierarchy', 'add_url': '/admin/auths/hierarchy/add/', 'name': <django.utils.functional.lazy.<locals>.__proxy__ object at 0x008376F0>, 'perms': {'change': True, 'add': True, 'delete': True}, 'admin_url': '/admin/auths/hierarchy/'}, {'object_name': 'Menu', 'add_url': '/admin/auths/menu/add/', 'name': <django.utils.functional.lazy.<locals>.__proxy__ object at 0x00837810>, 'perms': {'change': True, 'add': True, 'delete': True}, 'admin_url': '/admin/auths/menu/'}, {'object_name': 'Person', 'add_url': '/admin/auths/person/add/', 'name': <django.utils.functional.lazy.<locals>.__proxy__ object at 0x008375F0>, 'perms': {'change': True, 'add': True, 'delete': True}, 'admin_url': '/admin/auths/person/'}, {'object_name': 'UserHierarchyGroup', 'add_url': '/admin/auths/userhierarchygroup/add/', 'name': <django.utils.functional.lazy.<locals>.__proxy__ object at 0x00837930>, 'perms': {'change': True, 'add': True, 'delete': True}, 'admin_url': '/admin/auths/userhierarchygroup/'}, {'object_name': 'UserHierarchyPermission', 'add_url': '/admin/auths/userhierarchypermission/add/', 'name': <django.utils.functional.lazy.<locals>.__proxy__ object at 0x008378F0>, 'perms': {'change': True, 'add': True, 'delete': True}, 'admin_url': '/admin/auths/userhierarchypermission/'}, {'object_name': 'User', 'add_url': '/admin/auths/user/add/', 'name': <django.utils.functional.lazy.<locals>.__proxy__ object at 0x008377B0>, 'perms': {'change': True, 'add': True, 'delete': True}, 'admin_url': '/admin/auths/user/'}]}, {'has_module_perms': True, 'name': 'Catalogo', 'app_url': '/admin/catalogo/', 'app_label': 'catalogo', 'models': [{'object_name': 'Cabecera', 'add_url': '/admin/catalogo/cabecera/add/', 'name': <django.utils.functional.lazy.<locals>.__proxy__ object at 0x008376B0>, 'perms': {'change': True, 'add': True, 'delete': True}, 'admin_url': '/admin/catalogo/cabecera/'}, {'object_name': 'Cliente', 'add_url': '/admin/catalogo/cliente/add/', 'name': 'Clientes', 'perms': {'change': True, 'add': True, 'delete': True}, 'admin_url': '/admin/catalogo/cliente/'}, {'object_name': 'Distribuidor', 'add_url': '/admin/catalogo/distribuidor/add/', 'name': <django.utils.functional.lazy.<locals>.__proxy__ object at 0x00837770>, 'perms': {'change': True, 'add': True, 'delete': True}, 'admin_url': '/admin/catalogo/distribuidor/'}, {'object_name': 'Empresa', 'add_url': '/admin/catalogo/empresa/add/', 'name': <django.utils.functional.lazy.<locals>.__proxy__ object at 0x00837790>, 'perms': {'change': True, 'add': True, 'delete': True}, 'admin_url': '/admin/catalogo/empresa/'}, {'object_name': 'Presentacion', 'add_url': '/admin/catalogo/presentacion/add/', 'name': <django.utils.functional.lazy.<locals>.__proxy__ object at 0x00837830>, 'perms': {'change': True, 'add': True, 'delete': True}, 'admin_url': '/admin/catalogo/presentacion/'}, {'object_name': 'Producto', 'add_url': '/admin/catalogo/producto/add/', 'name': <django.utils.functional.lazy.<locals>.__proxy__ object at 0x008379B0>, 'perms': {'change': True, 'add': True, 'delete': True}, 'admin_url': '/admin/catalogo/producto/'}]}, {'has_module_perms': True, 'name': <django.utils.functional.lazy.<locals>.__proxy__ object at 0x037722F0>, 'app_url': '/admin/contenttypes/', 'app_label': 'contenttypes', 'models': [{'object_name': 'ContentType', 'add_url': '/admin/contenttypes/contenttype/add/', 'name': <django.utils.functional.lazy.<locals>.__proxy__ object at 0x00837710>, 'perms': {'change': True, 'add': True, 'delete': True}, 'admin_url': '/admin/contenttypes/contenttype/'}]}, {'has_module_perms': True, 'name': 'Django OAuth Toolkit', 'app_url': '/admin/oauth2_provider/', 'app_label': 'oauth2_provider', 'models': [{'object_name': 'AccessToken', 'add_url': '/admin/oauth2_provider/accesstoken/add/', 'name': <django.utils.functional.lazy.<locals>.__proxy__ object at 0x00837730>, 'perms': {'change': True, 'add': True, 'delete': True}, 'admin_url': '/admin/oauth2_provider/accesstoken/'}, {'object_name': 'Application', 'add_url': '/admin/oauth2_provider/application/add/', 'name': <django.utils.functional.lazy.<locals>.__proxy__ object at 0x00837870>, 'perms': {'change': True, 'add': True, 'delete': True}, 'admin_url': '/admin/oauth2_provider/application/'}, {'object_name': 'Grant', 'add_url': '/admin/oauth2_provider/grant/add/', 'name': <django.utils.functional.lazy.<locals>.__proxy__ object at 0x008377F0>, 'perms': {'change': True, 'add': True, 'delete': True}, 'admin_url': '/admin/oauth2_provider/grant/'}, {'object_name': 'RefreshToken', 'add_url': '/admin/oauth2_provider/refreshtoken/add/', 'name': <django.utils.functional.lazy.<locals>.__proxy__ object at 0x008379F0>, 'perms': {'change': True, 'add': True, 'delete': True}, 'admin_url': '/admin/oauth2_provider/refreshtoken/'}]}]}]"
[2016-11-01 12:00:20] DEBUG [django.template:927] Exception while resolving variable 'is_popup' in template 'admin/index.html'.
Traceback (most recent call last):
  File "D:\pydev\marketsoft\ve_market\lib\site-packages\django\template\base.py", line 883, in _resolve_lookup
    current = current[bit]
  File "D:\pydev\marketsoft\ve_market\lib\site-packages\django\template\context.py", line 77, in __getitem__
    raise KeyError(key)
KeyError: 'is_popup'

During handling of the above exception, another exception occurred:

Traceback (most recent call last):
  File "D:\pydev\marketsoft\ve_market\lib\site-packages\django\template\base.py", line 889, in _resolve_lookup
    if isinstance(current, BaseContext) and getattr(type(current), bit):
AttributeError: type object 'RequestContext' has no attribute 'is_popup'

During handling of the above exception, another exception occurred:

Traceback (most recent call last):
  File "D:\pydev\marketsoft\ve_market\lib\site-packages\django\template\base.py", line 898, in _resolve_lookup
    current = current[int(bit)]
ValueError: invalid literal for int() with base 10: 'is_popup'

During handling of the above exception, another exception occurred:

Traceback (most recent call last):
  File "D:\pydev\marketsoft\ve_market\lib\site-packages\django\template\base.py", line 905, in _resolve_lookup
    (bit, current))  # missing attribute
django.template.base.VariableDoesNotExist: Failed lookup for key [is_popup] in "[{'True': True, 'False': False, 'None': None}, {'user': <SimpleLazyObject: <User: admin>>, 'csrf_token': <SimpleLazyObject: <function csrf.<locals>._get_val at 0x04542C00>>, 'DEFAULT_MESSAGE_LEVELS': {'ERROR': 40, 'DEBUG': 10, 'SUCCESS': 25, 'INFO': 20, 'WARNING': 30}, 'request': <WSGIRequest: GET '/admin/'>, 'perms': <django.contrib.auth.context_processors.PermWrapper object at 0x0085B2D0>, 'messages': <django.contrib.messages.storage.fallback.FallbackStorage object at 0x0451EDD0>}, {}, {'has_permission': True, 'LANGUAGE_BIDI': False, 'site_header': <django.utils.functional.lazy.<locals>.__proxy__ object at 0x03766D30>, 'site_url': '/', 'app_list': [{'has_module_perms': True, 'name': <django.utils.functional.lazy.<locals>.__proxy__ object at 0x03772290>, 'app_url': '/admin/auth/', 'app_label': 'auth', 'models': [{'object_name': 'Group', 'add_url': '/admin/auth/group/add/', 'name': <django.utils.functional.lazy.<locals>.__proxy__ object at 0x00837450>, 'perms': {'change': True, 'add': True, 'delete': True}, 'admin_url': '/admin/auth/group/'}, {'object_name': 'Permission', 'add_url': '/admin/auth/permission/add/', 'name': <django.utils.functional.lazy.<locals>.__proxy__ object at 0x00837470>, 'perms': {'change': True, 'add': True, 'delete': True}, 'admin_url': '/admin/auth/permission/'}]}, {'has_module_perms': True, 'name': 'Auths', 'app_url': '/admin/auths/', 'app_label': 'auths', 'models': [{'object_name': 'HierarchyType', 'add_url': '/admin/auths/hierarchytype/add/', 'name': <django.utils.functional.lazy.<locals>.__proxy__ object at 0x0451E950>, 'perms': {'change': True, 'add': True, 'delete': True}, 'admin_url': '/admin/auths/hierarchytype/'}, {'object_name': 'Hierarchy', 'add_url': '/admin/auths/hierarchy/add/', 'name': <django.utils.functional.lazy.<locals>.__proxy__ object at 0x008373B0>, 'perms': {'change': True, 'add': True, 'delete': True}, 'admin_url': '/admin/auths/hierarchy/'}, {'object_name': 'Menu', 'add_url': '/admin/auths/menu/add/', 'name': <django.utils.functional.lazy.<locals>.__proxy__ object at 0x00837430>, 'perms': {'change': True, 'add': True, 'delete': True}, 'admin_url': '/admin/auths/menu/'}, {'object_name': 'Person', 'add_url': '/admin/auths/person/add/', 'name': <django.utils.functional.lazy.<locals>.__proxy__ object at 0x0454CFD0>, 'perms': {'change': True, 'add': True, 'delete': True}, 'admin_url': '/admin/auths/person/'}, {'object_name': 'UserHierarchyGroup', 'add_url': '/admin/auths/userhierarchygroup/add/', 'name': <django.utils.functional.lazy.<locals>.__proxy__ object at 0x008374F0>, 'perms': {'change': True, 'add': True, 'delete': True}, 'admin_url': '/admin/auths/userhierarchygroup/'}, {'object_name': 'UserHierarchyPermission', 'add_url': '/admin/auths/userhierarchypermission/add/', 'name': <django.utils.functional.lazy.<locals>.__proxy__ object at 0x008374D0>, 'perms': {'change': True, 'add': True, 'delete': True}, 'admin_url': '/admin/auths/userhierarchypermission/'}, {'object_name': 'User', 'add_url': '/admin/auths/user/add/', 'name': <django.utils.functional.lazy.<locals>.__proxy__ object at 0x008373D0>, 'perms': {'change': True, 'add': True, 'delete': True}, 'admin_url': '/admin/auths/user/'}]}, {'has_module_perms': True, 'name': 'Catalogo', 'app_url': '/admin/catalogo/', 'app_label': 'catalogo', 'models': [{'object_name': 'Cabecera', 'add_url': '/admin/catalogo/cabecera/add/', 'name': <django.utils.functional.lazy.<locals>.__proxy__ object at 0x00837390>, 'perms': {'change': True, 'add': True, 'delete': True}, 'admin_url': '/admin/catalogo/cabecera/'}, {'object_name': 'Cliente', 'add_url': '/admin/catalogo/cliente/add/', 'name': 'Clientes', 'perms': {'change': True, 'add': True, 'delete': True}, 'admin_url': '/admin/catalogo/cliente/'}, {'object_name': 'Distribuidor', 'add_url': '/admin/catalogo/distribuidor/add/', 'name': <django.utils.functional.lazy.<locals>.__proxy__ object at 0x008373F0>, 'perms': {'change': True, 'add': True, 'delete': True}, 'admin_url': '/admin/catalogo/distribuidor/'}, {'object_name': 'Empresa', 'add_url': '/admin/catalogo/empresa/add/', 'name': <django.utils.functional.lazy.<locals>.__proxy__ object at 0x0454CF70>, 'perms': {'change': True, 'add': True, 'delete': True}, 'admin_url': '/admin/catalogo/empresa/'}, {'object_name': 'Presentacion', 'add_url': '/admin/catalogo/presentacion/add/', 'name': <django.utils.functional.lazy.<locals>.__proxy__ object at 0x00837490>, 'perms': {'change': True, 'add': True, 'delete': True}, 'admin_url': '/admin/catalogo/presentacion/'}, {'object_name': 'Producto', 'add_url': '/admin/catalogo/producto/add/', 'name': <django.utils.functional.lazy.<locals>.__proxy__ object at 0x00837530>, 'perms': {'change': True, 'add': True, 'delete': True}, 'admin_url': '/admin/catalogo/producto/'}]}, {'has_module_perms': True, 'name': <django.utils.functional.lazy.<locals>.__proxy__ object at 0x037722F0>, 'app_url': '/admin/contenttypes/', 'app_label': 'contenttypes', 'models': [{'object_name': 'ContentType', 'add_url': '/admin/contenttypes/contenttype/add/', 'name': <django.utils.functional.lazy.<locals>.__proxy__ object at 0x0451E550>, 'perms': {'change': True, 'add': True, 'delete': True}, 'admin_url': '/admin/contenttypes/contenttype/'}]}, {'has_module_perms': True, 'name': 'Django OAuth Toolkit', 'app_url': '/admin/oauth2_provider/', 'app_label': 'oauth2_provider', 'models': [{'object_name': 'AccessToken', 'add_url': '/admin/oauth2_provider/accesstoken/add/', 'name': <django.utils.functional.lazy.<locals>.__proxy__ object at 0x00823DD0>, 'perms': {'change': True, 'add': True, 'delete': True}, 'admin_url': '/admin/oauth2_provider/accesstoken/'}, {'object_name': 'Application', 'add_url': '/admin/oauth2_provider/application/add/', 'name': <django.utils.functional.lazy.<locals>.__proxy__ object at 0x008374B0>, 'perms': {'change': True, 'add': True, 'delete': True}, 'admin_url': '/admin/oauth2_provider/application/'}, {'object_name': 'Grant', 'add_url': '/admin/oauth2_provider/grant/add/', 'name': <django.utils.functional.lazy.<locals>.__proxy__ object at 0x00837410>, 'perms': {'change': True, 'add': True, 'delete': True}, 'admin_url': '/admin/oauth2_provider/grant/'}, {'object_name': 'RefreshToken', 'add_url': '/admin/oauth2_provider/refreshtoken/add/', 'name': <django.utils.functional.lazy.<locals>.__proxy__ object at 0x00837550>, 'perms': {'change': True, 'add': True, 'delete': True}, 'admin_url': '/admin/oauth2_provider/refreshtoken/'}]}], 'site_title': <django.utils.functional.lazy.<locals>.__proxy__ object at 0x03766C70>, 'title': <django.utils.functional.lazy.<locals>.__proxy__ object at 0x03766D70>, 'LANGUAGE_CODE': 'en-us', 'available_apps': [{'has_module_perms': True, 'name': <django.utils.functional.lazy.<locals>.__proxy__ object at 0x03772290>, 'app_url': '/admin/auth/', 'app_label': 'auth', 'models': [{'object_name': 'Group', 'add_url': '/admin/auth/group/add/', 'name': <django.utils.functional.lazy.<locals>.__proxy__ object at 0x008378B0>, 'perms': {'change': True, 'add': True, 'delete': True}, 'admin_url': '/admin/auth/group/'}, {'object_name': 'Permission', 'add_url': '/admin/auth/permission/add/', 'name': <django.utils.functional.lazy.<locals>.__proxy__ object at 0x008377D0>, 'perms': {'change': True, 'add': True, 'delete': True}, 'admin_url': '/admin/auth/permission/'}]}, {'has_module_perms': True, 'name': 'Auths', 'app_url': '/admin/auths/', 'app_label': 'auths', 'models': [{'object_name': 'HierarchyType', 'add_url': '/admin/auths/hierarchytype/add/', 'name': <django.utils.functional.lazy.<locals>.__proxy__ object at 0x008375B0>, 'perms': {'change': True, 'add': True, 'delete': True}, 'admin_url': '/admin/auths/hierarchytype/'}, {'object_name': 'Hierarchy', 'add_url': '/admin/auths/hierarchy/add/', 'name': <django.utils.functional.lazy.<locals>.__proxy__ object at 0x008376F0>, 'perms': {'change': True, 'add': True, 'delete': True}, 'admin_url': '/admin/auths/hierarchy/'}, {'object_name': 'Menu', 'add_url': '/admin/auths/menu/add/', 'name': <django.utils.functional.lazy.<locals>.__proxy__ object at 0x00837810>, 'perms': {'change': True, 'add': True, 'delete': True}, 'admin_url': '/admin/auths/menu/'}, {'object_name': 'Person', 'add_url': '/admin/auths/person/add/', 'name': <django.utils.functional.lazy.<locals>.__proxy__ object at 0x008375F0>, 'perms': {'change': True, 'add': True, 'delete': True}, 'admin_url': '/admin/auths/person/'}, {'object_name': 'UserHierarchyGroup', 'add_url': '/admin/auths/userhierarchygroup/add/', 'name': <django.utils.functional.lazy.<locals>.__proxy__ object at 0x00837930>, 'perms': {'change': True, 'add': True, 'delete': True}, 'admin_url': '/admin/auths/userhierarchygroup/'}, {'object_name': 'UserHierarchyPermission', 'add_url': '/admin/auths/userhierarchypermission/add/', 'name': <django.utils.functional.lazy.<locals>.__proxy__ object at 0x008378F0>, 'perms': {'change': True, 'add': True, 'delete': True}, 'admin_url': '/admin/auths/userhierarchypermission/'}, {'object_name': 'User', 'add_url': '/admin/auths/user/add/', 'name': <django.utils.functional.lazy.<locals>.__proxy__ object at 0x008377B0>, 'perms': {'change': True, 'add': True, 'delete': True}, 'admin_url': '/admin/auths/user/'}]}, {'has_module_perms': True, 'name': 'Catalogo', 'app_url': '/admin/catalogo/', 'app_label': 'catalogo', 'models': [{'object_name': 'Cabecera', 'add_url': '/admin/catalogo/cabecera/add/', 'name': <django.utils.functional.lazy.<locals>.__proxy__ object at 0x008376B0>, 'perms': {'change': True, 'add': True, 'delete': True}, 'admin_url': '/admin/catalogo/cabecera/'}, {'object_name': 'Cliente', 'add_url': '/admin/catalogo/cliente/add/', 'name': 'Clientes', 'perms': {'change': True, 'add': True, 'delete': True}, 'admin_url': '/admin/catalogo/cliente/'}, {'object_name': 'Distribuidor', 'add_url': '/admin/catalogo/distribuidor/add/', 'name': <django.utils.functional.lazy.<locals>.__proxy__ object at 0x00837770>, 'perms': {'change': True, 'add': True, 'delete': True}, 'admin_url': '/admin/catalogo/distribuidor/'}, {'object_name': 'Empresa', 'add_url': '/admin/catalogo/empresa/add/', 'name': <django.utils.functional.lazy.<locals>.__proxy__ object at 0x00837790>, 'perms': {'change': True, 'add': True, 'delete': True}, 'admin_url': '/admin/catalogo/empresa/'}, {'object_name': 'Presentacion', 'add_url': '/admin/catalogo/presentacion/add/', 'name': <django.utils.functional.lazy.<locals>.__proxy__ object at 0x00837830>, 'perms': {'change': True, 'add': True, 'delete': True}, 'admin_url': '/admin/catalogo/presentacion/'}, {'object_name': 'Producto', 'add_url': '/admin/catalogo/producto/add/', 'name': <django.utils.functional.lazy.<locals>.__proxy__ object at 0x008379B0>, 'perms': {'change': True, 'add': True, 'delete': True}, 'admin_url': '/admin/catalogo/producto/'}]}, {'has_module_perms': True, 'name': <django.utils.functional.lazy.<locals>.__proxy__ object at 0x037722F0>, 'app_url': '/admin/contenttypes/', 'app_label': 'contenttypes', 'models': [{'object_name': 'ContentType', 'add_url': '/admin/contenttypes/contenttype/add/', 'name': <django.utils.functional.lazy.<locals>.__proxy__ object at 0x00837710>, 'perms': {'change': True, 'add': True, 'delete': True}, 'admin_url': '/admin/contenttypes/contenttype/'}]}, {'has_module_perms': True, 'name': 'Django OAuth Toolkit', 'app_url': '/admin/oauth2_provider/', 'app_label': 'oauth2_provider', 'models': [{'object_name': 'AccessToken', 'add_url': '/admin/oauth2_provider/accesstoken/add/', 'name': <django.utils.functional.lazy.<locals>.__proxy__ object at 0x00837730>, 'perms': {'change': True, 'add': True, 'delete': True}, 'admin_url': '/admin/oauth2_provider/accesstoken/'}, {'object_name': 'Application', 'add_url': '/admin/oauth2_provider/application/add/', 'name': <django.utils.functional.lazy.<locals>.__proxy__ object at 0x00837870>, 'perms': {'change': True, 'add': True, 'delete': True}, 'admin_url': '/admin/oauth2_provider/application/'}, {'object_name': 'Grant', 'add_url': '/admin/oauth2_provider/grant/add/', 'name': <django.utils.functional.lazy.<locals>.__proxy__ object at 0x008377F0>, 'perms': {'change': True, 'add': True, 'delete': True}, 'admin_url': '/admin/oauth2_provider/grant/'}, {'object_name': 'RefreshToken', 'add_url': '/admin/oauth2_provider/refreshtoken/add/', 'name': <django.utils.functional.lazy.<locals>.__proxy__ object at 0x008379F0>, 'perms': {'change': True, 'add': True, 'delete': True}, 'admin_url': '/admin/oauth2_provider/refreshtoken/'}]}]}]"
[2016-11-01 12:00:20] DEBUG [django.db.backends:89] (0.001) SELECT "django_admin_log"."id", "django_admin_log"."action_time", "django_admin_log"."user_id", "django_admin_log"."content_type_id", "django_admin_log"."object_id", "django_admin_log"."object_repr", "django_admin_log"."action_flag", "django_admin_log"."change_message", "auths_user"."password", "auths_user"."last_login", "auths_user"."is_superuser", "auths_user"."username", "auths_user"."first_name", "auths_user"."last_name", "auths_user"."email", "auths_user"."is_staff", "auths_user"."is_active", "auths_user"."date_joined", "auths_user"."id", "auths_user"."last_hierarchy_id", "auths_user"."last_module_id", "auths_user"."person_id", "auths_user"."updated_at", "auths_user"."registered_by", "django_content_type"."id", "django_content_type"."app_label", "django_content_type"."model" FROM "django_admin_log" INNER JOIN "auths_user" ON ("django_admin_log"."user_id" = "auths_user"."id") LEFT OUTER JOIN "django_content_type" ON ("django_admin_log"."content_type_id" = "django_content_type"."id") WHERE "django_admin_log"."user_id" = '4c7e4779b6bd47198afbd9e574b13d0a' ORDER BY "django_admin_log"."action_time" DESC LIMIT 10; args=('4c7e4779b6bd47198afbd9e574b13d0a',)
[2016-11-01 12:00:25] DEBUG [django.db.backends:89] (0.002) SELECT "django_session"."session_key", "django_session"."session_data", "django_session"."expire_date" FROM "django_session" WHERE ("django_session"."expire_date" > '2016-11-01 17:00:25.612818' AND "django_session"."session_key" = 'gtw0v45oztxiziavd0vcwh57etmeavi6'); args=('2016-11-01 17:00:25.612818', 'gtw0v45oztxiziavd0vcwh57etmeavi6')
[2016-11-01 12:00:25] DEBUG [django.db.backends:89] (0.000) SELECT "auths_user"."password", "auths_user"."last_login", "auths_user"."is_superuser", "auths_user"."username", "auths_user"."first_name", "auths_user"."last_name", "auths_user"."email", "auths_user"."is_staff", "auths_user"."is_active", "auths_user"."date_joined", "auths_user"."id", "auths_user"."last_hierarchy_id", "auths_user"."last_module_id", "auths_user"."person_id", "auths_user"."updated_at", "auths_user"."registered_by" FROM "auths_user" WHERE "auths_user"."id" = '4c7e4779b6bd47198afbd9e574b13d0a'; args=('4c7e4779b6bd47198afbd9e574b13d0a',)
[2016-11-01 12:00:25] DEBUG [django.db.backends:89] (0.001) SELECT COUNT(*) AS "__count" FROM "catalogo_cabecera"; args=()
[2016-11-01 12:00:25] DEBUG [django.db.backends:89] (0.000) SELECT "catalogo_cabecera"."created", "catalogo_cabecera"."modified", "catalogo_cabecera"."id", "catalogo_cabecera"."trabajador_id", "catalogo_cabecera"."codigo", "catalogo_cabecera"."distribuidor_id", "catalogo_cabecera"."empresa_id", "catalogo_cabecera"."fecha" FROM "catalogo_cabecera" ORDER BY "catalogo_cabecera"."id" DESC; args=()
[2016-11-01 12:00:25] DEBUG [django.template:927] Exception while resolving variable 'errors' in template 'admin/change_list.html'.
Traceback (most recent call last):
  File "D:\pydev\marketsoft\ve_market\lib\site-packages\django\template\base.py", line 883, in _resolve_lookup
    current = current[bit]
TypeError: 'NoneType' object is not subscriptable

During handling of the above exception, another exception occurred:

Traceback (most recent call last):
  File "D:\pydev\marketsoft\ve_market\lib\site-packages\django\template\base.py", line 891, in _resolve_lookup
    current = getattr(current, bit)
AttributeError: 'NoneType' object has no attribute 'errors'

During handling of the above exception, another exception occurred:

Traceback (most recent call last):
  File "D:\pydev\marketsoft\ve_market\lib\site-packages\django\template\base.py", line 898, in _resolve_lookup
    current = current[int(bit)]
ValueError: invalid literal for int() with base 10: 'errors'

During handling of the above exception, another exception occurred:

Traceback (most recent call last):
  File "D:\pydev\marketsoft\ve_market\lib\site-packages\django\template\base.py", line 905, in _resolve_lookup
    (bit, current))  # missing attribute
django.template.base.VariableDoesNotExist: Failed lookup for key [errors] in 'None'
[2016-11-01 12:00:25] DEBUG [django.template:927] Exception while resolving variable 'show' in template 'admin/change_list.html'.
Traceback (most recent call last):
  File "D:\pydev\marketsoft\ve_market\lib\site-packages\django\template\base.py", line 883, in _resolve_lookup
    current = current[bit]
  File "D:\pydev\marketsoft\ve_market\lib\site-packages\django\template\context.py", line 77, in __getitem__
    raise KeyError(key)
KeyError: 'show'

During handling of the above exception, another exception occurred:

Traceback (most recent call last):
  File "D:\pydev\marketsoft\ve_market\lib\site-packages\django\template\base.py", line 889, in _resolve_lookup
    if isinstance(current, BaseContext) and getattr(type(current), bit):
AttributeError: type object 'RequestContext' has no attribute 'show'

During handling of the above exception, another exception occurred:

Traceback (most recent call last):
  File "D:\pydev\marketsoft\ve_market\lib\site-packages\django\template\base.py", line 898, in _resolve_lookup
    current = current[int(bit)]
ValueError: invalid literal for int() with base 10: 'show'

During handling of the above exception, another exception occurred:

Traceback (most recent call last):
  File "D:\pydev\marketsoft\ve_market\lib\site-packages\django\template\base.py", line 905, in _resolve_lookup
    (bit, current))  # missing attribute
django.template.base.VariableDoesNotExist: Failed lookup for key [show] in "[{'True': True, 'csrf_token': <SimpleLazyObject: <function csrf.<locals>._get_val at 0x0085E468>>, 'False': False, 'None': None}]"
[2016-11-01 12:00:25] DEBUG [django.template:927] Exception while resolving variable 'is_multipart' in template 'admin/change_list.html'.
Traceback (most recent call last):
  File "D:\pydev\marketsoft\ve_market\lib\site-packages\django\template\base.py", line 883, in _resolve_lookup
    current = current[bit]
TypeError: 'NoneType' object is not subscriptable

During handling of the above exception, another exception occurred:

Traceback (most recent call last):
  File "D:\pydev\marketsoft\ve_market\lib\site-packages\django\template\base.py", line 891, in _resolve_lookup
    current = getattr(current, bit)
AttributeError: 'NoneType' object has no attribute 'is_multipart'

During handling of the above exception, another exception occurred:

Traceback (most recent call last):
  File "D:\pydev\marketsoft\ve_market\lib\site-packages\django\template\base.py", line 898, in _resolve_lookup
    current = current[int(bit)]
ValueError: invalid literal for int() with base 10: 'is_multipart'

During handling of the above exception, another exception occurred:

Traceback (most recent call last):
  File "D:\pydev\marketsoft\ve_market\lib\site-packages\django\template\base.py", line 905, in _resolve_lookup
    (bit, current))  # missing attribute
django.template.base.VariableDoesNotExist: Failed lookup for key [is_multipart] in 'None'
[2016-11-01 12:00:26] DEBUG [django.db.backends:89] (0.002) SELECT "django_session"."session_key", "django_session"."session_data", "django_session"."expire_date" FROM "django_session" WHERE ("django_session"."expire_date" > '2016-11-01 17:00:26.005089' AND "django_session"."session_key" = 'gtw0v45oztxiziavd0vcwh57etmeavi6'); args=('2016-11-01 17:00:26.005089', 'gtw0v45oztxiziavd0vcwh57etmeavi6')
[2016-11-01 12:00:26] DEBUG [django.db.backends:89] (0.000) SELECT "auths_user"."password", "auths_user"."last_login", "auths_user"."is_superuser", "auths_user"."username", "auths_user"."first_name", "auths_user"."last_name", "auths_user"."email", "auths_user"."is_staff", "auths_user"."is_active", "auths_user"."date_joined", "auths_user"."id", "auths_user"."last_hierarchy_id", "auths_user"."last_module_id", "auths_user"."person_id", "auths_user"."updated_at", "auths_user"."registered_by" FROM "auths_user" WHERE "auths_user"."id" = '4c7e4779b6bd47198afbd9e574b13d0a'; args=('4c7e4779b6bd47198afbd9e574b13d0a',)
[2016-11-01 12:00:28] DEBUG [django.db.backends:89] (0.005) SELECT "django_session"."session_key", "django_session"."session_data", "django_session"."expire_date" FROM "django_session" WHERE ("django_session"."expire_date" > '2016-11-01 17:00:28.109034' AND "django_session"."session_key" = 'gtw0v45oztxiziavd0vcwh57etmeavi6'); args=('2016-11-01 17:00:28.109034', 'gtw0v45oztxiziavd0vcwh57etmeavi6')
[2016-11-01 12:00:28] DEBUG [django.db.backends:89] (0.001) SELECT "auths_user"."password", "auths_user"."last_login", "auths_user"."is_superuser", "auths_user"."username", "auths_user"."first_name", "auths_user"."last_name", "auths_user"."email", "auths_user"."is_staff", "auths_user"."is_active", "auths_user"."date_joined", "auths_user"."id", "auths_user"."last_hierarchy_id", "auths_user"."last_module_id", "auths_user"."person_id", "auths_user"."updated_at", "auths_user"."registered_by" FROM "auths_user" WHERE "auths_user"."id" = '4c7e4779b6bd47198afbd9e574b13d0a'; args=('4c7e4779b6bd47198afbd9e574b13d0a',)
[2016-11-01 12:00:28] DEBUG [django.db.backends:89] (0.000) BEGIN; args=None
[2016-11-01 12:00:28] DEBUG [django.db.backends:89] (0.000) SELECT "catalogo_detallecompra"."id", "catalogo_detallecompra"."list_id", "catalogo_detallecompra"."producto_id", "catalogo_detallecompra"."cantidad" FROM "catalogo_detallecompra" WHERE "catalogo_detallecompra"."list_id" = 'a5ee0e9f6ee847ee89a57e820d744e9b' ORDER BY "catalogo_detallecompra"."id" ASC; args=('a5ee0e9f6ee847ee89a57e820d744e9b',)
[2016-11-01 12:00:28] DEBUG [django.db.backends:89] (0.000) SELECT "django_content_type"."id", "django_content_type"."app_label", "django_content_type"."model" FROM "django_content_type" WHERE ("django_content_type"."model" = 'cabecera' AND "django_content_type"."app_label" = 'catalogo'); args=('cabecera', 'catalogo')
[2016-11-01 12:00:28] DEBUG [django.db.backends:89] (0.000) SELECT "auths_user"."password", "auths_user"."last_login", "auths_user"."is_superuser", "auths_user"."username", "auths_user"."first_name", "auths_user"."last_name", "auths_user"."email", "auths_user"."is_staff", "auths_user"."is_active", "auths_user"."date_joined", "auths_user"."id", "auths_user"."last_hierarchy_id", "auths_user"."last_module_id", "auths_user"."person_id", "auths_user"."updated_at", "auths_user"."registered_by" FROM "auths_user" ORDER BY "auths_user"."username" ASC; args=()
[2016-11-01 12:00:28] DEBUG [django.template:927] Exception while resolving variable 'can_delete_related' in template 'admin/related_widget_wrapper.html'.
Traceback (most recent call last):
  File "D:\pydev\marketsoft\ve_market\lib\site-packages\django\template\base.py", line 883, in _resolve_lookup
    current = current[bit]
  File "D:\pydev\marketsoft\ve_market\lib\site-packages\django\template\context.py", line 77, in __getitem__
    raise KeyError(key)
KeyError: 'can_delete_related'

During handling of the above exception, another exception occurred:

Traceback (most recent call last):
  File "D:\pydev\marketsoft\ve_market\lib\site-packages\django\template\base.py", line 889, in _resolve_lookup
    if isinstance(current, BaseContext) and getattr(type(current), bit):
AttributeError: type object 'Context' has no attribute 'can_delete_related'

During handling of the above exception, another exception occurred:

Traceback (most recent call last):
  File "D:\pydev\marketsoft\ve_market\lib\site-packages\django\template\base.py", line 898, in _resolve_lookup
    current = current[int(bit)]
ValueError: invalid literal for int() with base 10: 'can_delete_related'

During handling of the above exception, another exception occurred:

Traceback (most recent call last):
  File "D:\pydev\marketsoft\ve_market\lib\site-packages\django\template\base.py", line 905, in _resolve_lookup
    (bit, current))  # missing attribute
django.template.base.VariableDoesNotExist: Failed lookup for key [can_delete_related] in '[{\'True\': True, \'False\': False, \'None\': None}, {\'can_add_related\': True, \'model\': <django.utils.functional.lazy.<locals>.__proxy__ object at 0x03C61EF0>, \'widget\': \'<select id="id_trabajador" name="trabajador">\\n<option value="" selected="selected">---------</option>\\n<option value="4c7e4779-b6bd-4719-8afb-d9e574b13d0a">admin</option>\\n<option value="e0174614-c5f0-4049-9a30-a1790c8ff7e9">user</option>\\n</select>\', \'url_params\': \'_to_field=id&_popup=1\', \'can_change_related\': True, \'name\': \'trabajador\', \'change_related_template_url\': \'/admin/auths/user/__fk__/change/\', \'add_related_url\': \'/admin/auths/user/add/\'}, {\'block\': <Block Node: links. Contents: [<TextNode: \'\\n        \'>, <IfNode>, <TextNode: \'\\n        \'>, <IfNode>, <TextNode: \'\\n        \'>, <IfNode>, <TextNode: \'\\n    \'>]>}]'
[2016-11-01 12:00:28] DEBUG [django.db.backends:89] (0.000) SELECT "catalogo_distribuidor"."id", "catalogo_distribuidor"."nombre", "catalogo_distribuidor"."ruc", "catalogo_distribuidor"."telefono", "catalogo_distribuidor"."direccion" FROM "catalogo_distribuidor"; args=()
[2016-11-01 12:00:28] DEBUG [django.template:927] Exception while resolving variable 'can_delete_related' in template 'admin/related_widget_wrapper.html'.
Traceback (most recent call last):
  File "D:\pydev\marketsoft\ve_market\lib\site-packages\django\template\base.py", line 883, in _resolve_lookup
    current = current[bit]
  File "D:\pydev\marketsoft\ve_market\lib\site-packages\django\template\context.py", line 77, in __getitem__
    raise KeyError(key)
KeyError: 'can_delete_related'

During handling of the above exception, another exception occurred:

Traceback (most recent call last):
  File "D:\pydev\marketsoft\ve_market\lib\site-packages\django\template\base.py", line 889, in _resolve_lookup
    if isinstance(current, BaseContext) and getattr(type(current), bit):
AttributeError: type object 'Context' has no attribute 'can_delete_related'

During handling of the above exception, another exception occurred:

Traceback (most recent call last):
  File "D:\pydev\marketsoft\ve_market\lib\site-packages\django\template\base.py", line 898, in _resolve_lookup
    current = current[int(bit)]
ValueError: invalid literal for int() with base 10: 'can_delete_related'

During handling of the above exception, another exception occurred:

Traceback (most recent call last):
  File "D:\pydev\marketsoft\ve_market\lib\site-packages\django\template\base.py", line 905, in _resolve_lookup
    (bit, current))  # missing attribute
django.template.base.VariableDoesNotExist: Failed lookup for key [can_delete_related] in '[{\'True\': True, \'False\': False, \'None\': None}, {\'can_add_related\': True, \'model\': \'distribuidor\', \'widget\': \'<select id="id_distribuidor" name="distribuidor">\\n<option value="" selected="selected">---------</option>\\n</select>\', \'url_params\': \'_to_field=id&_popup=1\', \'can_change_related\': True, \'name\': \'distribuidor\', \'change_related_template_url\': \'/admin/catalogo/distribuidor/__fk__/change/\', \'add_related_url\': \'/admin/catalogo/distribuidor/add/\'}, {\'block\': <Block Node: links. Contents: [<TextNode: \'\\n        \'>, <IfNode>, <TextNode: \'\\n        \'>, <IfNode>, <TextNode: \'\\n        \'>, <IfNode>, <TextNode: \'\\n    \'>]>}]'
[2016-11-01 12:00:28] DEBUG [django.db.backends:89] (0.000) SELECT "catalogo_empresa"."id", "catalogo_empresa"."ruc", "catalogo_empresa"."nombre", "catalogo_empresa"."direccion" FROM "catalogo_empresa"; args=()
[2016-11-01 12:00:28] DEBUG [django.template:927] Exception while resolving variable 'can_delete_related' in template 'admin/related_widget_wrapper.html'.
Traceback (most recent call last):
  File "D:\pydev\marketsoft\ve_market\lib\site-packages\django\template\base.py", line 883, in _resolve_lookup
    current = current[bit]
  File "D:\pydev\marketsoft\ve_market\lib\site-packages\django\template\context.py", line 77, in __getitem__
    raise KeyError(key)
KeyError: 'can_delete_related'

During handling of the above exception, another exception occurred:

Traceback (most recent call last):
  File "D:\pydev\marketsoft\ve_market\lib\site-packages\django\template\base.py", line 889, in _resolve_lookup
    if isinstance(current, BaseContext) and getattr(type(current), bit):
AttributeError: type object 'Context' has no attribute 'can_delete_related'

During handling of the above exception, another exception occurred:

Traceback (most recent call last):
  File "D:\pydev\marketsoft\ve_market\lib\site-packages\django\template\base.py", line 898, in _resolve_lookup
    current = current[int(bit)]
ValueError: invalid literal for int() with base 10: 'can_delete_related'

During handling of the above exception, another exception occurred:

Traceback (most recent call last):
  File "D:\pydev\marketsoft\ve_market\lib\site-packages\django\template\base.py", line 905, in _resolve_lookup
    (bit, current))  # missing attribute
django.template.base.VariableDoesNotExist: Failed lookup for key [can_delete_related] in '[{\'True\': True, \'False\': False, \'None\': None}, {\'can_add_related\': True, \'model\': \'empresa\', \'widget\': \'<select id="id_empresa" name="empresa">\\n<option value="" selected="selected">---------</option>\\n</select>\', \'url_params\': \'_to_field=id&_popup=1\', \'can_change_related\': True, \'name\': \'empresa\', \'change_related_template_url\': \'/admin/catalogo/empresa/__fk__/change/\', \'add_related_url\': \'/admin/catalogo/empresa/add/\'}, {\'block\': <Block Node: links. Contents: [<TextNode: \'\\n        \'>, <IfNode>, <TextNode: \'\\n        \'>, <IfNode>, <TextNode: \'\\n        \'>, <IfNode>, <TextNode: \'\\n    \'>]>}]'
[2016-11-01 12:00:28] DEBUG [django.db.backends:89] (0.000) SELECT "catalogo_producto"."id", "catalogo_producto"."lote", "catalogo_producto"."presentacion_id", "catalogo_producto"."tipo", "catalogo_producto"."nombre", "catalogo_producto"."componente", "catalogo_producto"."concentracion", "catalogo_producto"."sanitario", "catalogo_producto"."fecha_expiracion", "catalogo_producto"."fecha_produccion", "catalogo_producto"."descripcion", "catalogo_producto"."precio_Compra", "catalogo_producto"."precio_venta", "catalogo_producto"."stock", "catalogo_producto"."igv" FROM "catalogo_producto"; args=()
[2016-11-01 12:00:28] DEBUG [django.template:927] Exception while resolving variable 'can_delete_related' in template 'admin/related_widget_wrapper.html'.
Traceback (most recent call last):
  File "D:\pydev\marketsoft\ve_market\lib\site-packages\django\template\base.py", line 883, in _resolve_lookup
    current = current[bit]
  File "D:\pydev\marketsoft\ve_market\lib\site-packages\django\template\context.py", line 77, in __getitem__
    raise KeyError(key)
KeyError: 'can_delete_related'

During handling of the above exception, another exception occurred:

Traceback (most recent call last):
  File "D:\pydev\marketsoft\ve_market\lib\site-packages\django\template\base.py", line 889, in _resolve_lookup
    if isinstance(current, BaseContext) and getattr(type(current), bit):
AttributeError: type object 'Context' has no attribute 'can_delete_related'

During handling of the above exception, another exception occurred:

Traceback (most recent call last):
  File "D:\pydev\marketsoft\ve_market\lib\site-packages\django\template\base.py", line 898, in _resolve_lookup
    current = current[int(bit)]
ValueError: invalid literal for int() with base 10: 'can_delete_related'

During handling of the above exception, another exception occurred:

Traceback (most recent call last):
  File "D:\pydev\marketsoft\ve_market\lib\site-packages\django\template\base.py", line 905, in _resolve_lookup
    (bit, current))  # missing attribute
django.template.base.VariableDoesNotExist: Failed lookup for key [can_delete_related] in '[{\'True\': True, \'False\': False, \'None\': None}, {\'can_add_related\': True, \'model\': \'producto\', \'widget\': \'<select id="id_cabecera-0-producto" name="cabecera-0-producto">\\n<option value="" selected="selected">---------</option>\\n</select>\', \'url_params\': \'_to_field=id&_popup=1\', \'can_change_related\': True, \'name\': \'cabecera-0-producto\', \'change_related_template_url\': \'/admin/catalogo/producto/__fk__/change/\', \'add_related_url\': \'/admin/catalogo/producto/add/\'}, {\'block\': <Block Node: links. Contents: [<TextNode: \'\\n        \'>, <IfNode>, <TextNode: \'\\n        \'>, <IfNode>, <TextNode: \'\\n        \'>, <IfNode>, <TextNode: \'\\n    \'>]>}]'
[2016-11-01 12:00:28] DEBUG [django.db.backends:89] (0.000) SELECT "catalogo_producto"."id", "catalogo_producto"."lote", "catalogo_producto"."presentacion_id", "catalogo_producto"."tipo", "catalogo_producto"."nombre", "catalogo_producto"."componente", "catalogo_producto"."concentracion", "catalogo_producto"."sanitario", "catalogo_producto"."fecha_expiracion", "catalogo_producto"."fecha_produccion", "catalogo_producto"."descripcion", "catalogo_producto"."precio_Compra", "catalogo_producto"."precio_venta", "catalogo_producto"."stock", "catalogo_producto"."igv" FROM "catalogo_producto"; args=()
[2016-11-01 12:00:28] DEBUG [django.template:927] Exception while resolving variable 'can_delete_related' in template 'admin/related_widget_wrapper.html'.
Traceback (most recent call last):
  File "D:\pydev\marketsoft\ve_market\lib\site-packages\django\template\base.py", line 883, in _resolve_lookup
    current = current[bit]
  File "D:\pydev\marketsoft\ve_market\lib\site-packages\django\template\context.py", line 77, in __getitem__
    raise KeyError(key)
KeyError: 'can_delete_related'

During handling of the above exception, another exception occurred:

Traceback (most recent call last):
  File "D:\pydev\marketsoft\ve_market\lib\site-packages\django\template\base.py", line 889, in _resolve_lookup
    if isinstance(current, BaseContext) and getattr(type(current), bit):
AttributeError: type object 'Context' has no attribute 'can_delete_related'

During handling of the above exception, another exception occurred:

Traceback (most recent call last):
  File "D:\pydev\marketsoft\ve_market\lib\site-packages\django\template\base.py", line 898, in _resolve_lookup
    current = current[int(bit)]
ValueError: invalid literal for int() with base 10: 'can_delete_related'

During handling of the above exception, another exception occurred:

Traceback (most recent call last):
  File "D:\pydev\marketsoft\ve_market\lib\site-packages\django\template\base.py", line 905, in _resolve_lookup
    (bit, current))  # missing attribute
django.template.base.VariableDoesNotExist: Failed lookup for key [can_delete_related] in '[{\'True\': True, \'False\': False, \'None\': None}, {\'can_add_related\': True, \'model\': \'producto\', \'widget\': \'<select id="id_cabecera-1-producto" name="cabecera-1-producto">\\n<option value="" selected="selected">---------</option>\\n</select>\', \'url_params\': \'_to_field=id&_popup=1\', \'can_change_related\': True, \'name\': \'cabecera-1-producto\', \'change_related_template_url\': \'/admin/catalogo/producto/__fk__/change/\', \'add_related_url\': \'/admin/catalogo/producto/add/\'}, {\'block\': <Block Node: links. Contents: [<TextNode: \'\\n        \'>, <IfNode>, <TextNode: \'\\n        \'>, <IfNode>, <TextNode: \'\\n        \'>, <IfNode>, <TextNode: \'\\n    \'>]>}]'
[2016-11-01 12:00:28] DEBUG [django.db.backends:89] (0.000) SELECT "catalogo_producto"."id", "catalogo_producto"."lote", "catalogo_producto"."presentacion_id", "catalogo_producto"."tipo", "catalogo_producto"."nombre", "catalogo_producto"."componente", "catalogo_producto"."concentracion", "catalogo_producto"."sanitario", "catalogo_producto"."fecha_expiracion", "catalogo_producto"."fecha_produccion", "catalogo_producto"."descripcion", "catalogo_producto"."precio_Compra", "catalogo_producto"."precio_venta", "catalogo_producto"."stock", "catalogo_producto"."igv" FROM "catalogo_producto"; args=()
[2016-11-01 12:00:28] DEBUG [django.template:927] Exception while resolving variable 'can_delete_related' in template 'admin/related_widget_wrapper.html'.
Traceback (most recent call last):
  File "D:\pydev\marketsoft\ve_market\lib\site-packages\django\template\base.py", line 883, in _resolve_lookup
    current = current[bit]
  File "D:\pydev\marketsoft\ve_market\lib\site-packages\django\template\context.py", line 77, in __getitem__
    raise KeyError(key)
KeyError: 'can_delete_related'

During handling of the above exception, another exception occurred:

Traceback (most recent call last):
  File "D:\pydev\marketsoft\ve_market\lib\site-packages\django\template\base.py", line 889, in _resolve_lookup
    if isinstance(current, BaseContext) and getattr(type(current), bit):
AttributeError: type object 'Context' has no attribute 'can_delete_related'

During handling of the above exception, another exception occurred:

Traceback (most recent call last):
  File "D:\pydev\marketsoft\ve_market\lib\site-packages\django\template\base.py", line 898, in _resolve_lookup
    current = current[int(bit)]
ValueError: invalid literal for int() with base 10: 'can_delete_related'

During handling of the above exception, another exception occurred:

Traceback (most recent call last):
  File "D:\pydev\marketsoft\ve_market\lib\site-packages\django\template\base.py", line 905, in _resolve_lookup
    (bit, current))  # missing attribute
django.template.base.VariableDoesNotExist: Failed lookup for key [can_delete_related] in '[{\'True\': True, \'False\': False, \'None\': None}, {\'can_add_related\': True, \'model\': \'producto\', \'widget\': \'<select id="id_cabecera-2-producto" name="cabecera-2-producto">\\n<option value="" selected="selected">---------</option>\\n</select>\', \'url_params\': \'_to_field=id&_popup=1\', \'can_change_related\': True, \'name\': \'cabecera-2-producto\', \'change_related_template_url\': \'/admin/catalogo/producto/__fk__/change/\', \'add_related_url\': \'/admin/catalogo/producto/add/\'}, {\'block\': <Block Node: links. Contents: [<TextNode: \'\\n        \'>, <IfNode>, <TextNode: \'\\n        \'>, <IfNode>, <TextNode: \'\\n        \'>, <IfNode>, <TextNode: \'\\n    \'>]>}]'
[2016-11-01 12:00:28] DEBUG [django.db.backends:89] (0.001) SELECT "catalogo_producto"."id", "catalogo_producto"."lote", "catalogo_producto"."presentacion_id", "catalogo_producto"."tipo", "catalogo_producto"."nombre", "catalogo_producto"."componente", "catalogo_producto"."concentracion", "catalogo_producto"."sanitario", "catalogo_producto"."fecha_expiracion", "catalogo_producto"."fecha_produccion", "catalogo_producto"."descripcion", "catalogo_producto"."precio_Compra", "catalogo_producto"."precio_venta", "catalogo_producto"."stock", "catalogo_producto"."igv" FROM "catalogo_producto"; args=()
[2016-11-01 12:00:28] DEBUG [django.template:927] Exception while resolving variable 'can_delete_related' in template 'admin/related_widget_wrapper.html'.
Traceback (most recent call last):
  File "D:\pydev\marketsoft\ve_market\lib\site-packages\django\template\base.py", line 883, in _resolve_lookup
    current = current[bit]
  File "D:\pydev\marketsoft\ve_market\lib\site-packages\django\template\context.py", line 77, in __getitem__
    raise KeyError(key)
KeyError: 'can_delete_related'

During handling of the above exception, another exception occurred:

Traceback (most recent call last):
  File "D:\pydev\marketsoft\ve_market\lib\site-packages\django\template\base.py", line 889, in _resolve_lookup
    if isinstance(current, BaseContext) and getattr(type(current), bit):
AttributeError: type object 'Context' has no attribute 'can_delete_related'

During handling of the above exception, another exception occurred:

Traceback (most recent call last):
  File "D:\pydev\marketsoft\ve_market\lib\site-packages\django\template\base.py", line 898, in _resolve_lookup
    current = current[int(bit)]
ValueError: invalid literal for int() with base 10: 'can_delete_related'

During handling of the above exception, another exception occurred:

Traceback (most recent call last):
  File "D:\pydev\marketsoft\ve_market\lib\site-packages\django\template\base.py", line 905, in _resolve_lookup
    (bit, current))  # missing attribute
django.template.base.VariableDoesNotExist: Failed lookup for key [can_delete_related] in '[{\'True\': True, \'False\': False, \'None\': None}, {\'can_add_related\': True, \'model\': \'producto\', \'widget\': \'<select id="id_cabecera-__prefix__-producto" name="cabecera-__prefix__-producto">\\n<option value="" selected="selected">---------</option>\\n</select>\', \'url_params\': \'_to_field=id&_popup=1\', \'can_change_related\': True, \'name\': \'cabecera-__prefix__-producto\', \'change_related_template_url\': \'/admin/catalogo/producto/__fk__/change/\', \'add_related_url\': \'/admin/catalogo/producto/add/\'}, {\'block\': <Block Node: links. Contents: [<TextNode: \'\\n        \'>, <IfNode>, <TextNode: \'\\n        \'>, <IfNode>, <TextNode: \'\\n        \'>, <IfNode>, <TextNode: \'\\n    \'>]>}]'
[2016-11-01 12:00:28] DEBUG [django.db.backends:89] (0.002) SELECT "django_session"."session_key", "django_session"."session_data", "django_session"."expire_date" FROM "django_session" WHERE ("django_session"."expire_date" > '2016-11-01 17:00:28.533217' AND "django_session"."session_key" = 'gtw0v45oztxiziavd0vcwh57etmeavi6'); args=('2016-11-01 17:00:28.533217', 'gtw0v45oztxiziavd0vcwh57etmeavi6')
[2016-11-01 12:00:28] DEBUG [django.db.backends:89] (0.001) SELECT "auths_user"."password", "auths_user"."last_login", "auths_user"."is_superuser", "auths_user"."username", "auths_user"."first_name", "auths_user"."last_name", "auths_user"."email", "auths_user"."is_staff", "auths_user"."is_active", "auths_user"."date_joined", "auths_user"."id", "auths_user"."last_hierarchy_id", "auths_user"."last_module_id", "auths_user"."person_id", "auths_user"."updated_at", "auths_user"."registered_by" FROM "auths_user" WHERE "auths_user"."id" = '4c7e4779b6bd47198afbd9e574b13d0a'; args=('4c7e4779b6bd47198afbd9e574b13d0a',)
[2016-11-01 12:00:44] DEBUG [django.db.backends:89] (0.002) SELECT "django_session"."session_key", "django_session"."session_data", "django_session"."expire_date" FROM "django_session" WHERE ("django_session"."expire_date" > '2016-11-01 17:00:44.522905' AND "django_session"."session_key" = 'gtw0v45oztxiziavd0vcwh57etmeavi6'); args=('2016-11-01 17:00:44.522905', 'gtw0v45oztxiziavd0vcwh57etmeavi6')
[2016-11-01 12:00:44] DEBUG [django.db.backends:89] (0.000) SELECT "auths_user"."password", "auths_user"."last_login", "auths_user"."is_superuser", "auths_user"."username", "auths_user"."first_name", "auths_user"."last_name", "auths_user"."email", "auths_user"."is_staff", "auths_user"."is_active", "auths_user"."date_joined", "auths_user"."id", "auths_user"."last_hierarchy_id", "auths_user"."last_module_id", "auths_user"."person_id", "auths_user"."updated_at", "auths_user"."registered_by" FROM "auths_user" WHERE "auths_user"."id" = '4c7e4779b6bd47198afbd9e574b13d0a'; args=('4c7e4779b6bd47198afbd9e574b13d0a',)
[2016-11-01 12:00:44] DEBUG [django.db.backends:89] (0.000) BEGIN; args=None
[2016-11-01 12:00:44] DEBUG [django.db.backends:89] (0.000) SELECT "django_content_type"."id", "django_content_type"."app_label", "django_content_type"."model" FROM "django_content_type" WHERE ("django_content_type"."model" = 'distribuidor' AND "django_content_type"."app_label" = 'catalogo'); args=('distribuidor', 'catalogo')
[2016-11-01 12:00:44] DEBUG [django.db.backends:89] (0.004) SELECT "django_session"."session_key", "django_session"."session_data", "django_session"."expire_date" FROM "django_session" WHERE ("django_session"."expire_date" > '2016-11-01 17:00:44.672011' AND "django_session"."session_key" = 'gtw0v45oztxiziavd0vcwh57etmeavi6'); args=('2016-11-01 17:00:44.672011', 'gtw0v45oztxiziavd0vcwh57etmeavi6')
[2016-11-01 12:00:44] DEBUG [django.db.backends:89] (0.001) SELECT "auths_user"."password", "auths_user"."last_login", "auths_user"."is_superuser", "auths_user"."username", "auths_user"."first_name", "auths_user"."last_name", "auths_user"."email", "auths_user"."is_staff", "auths_user"."is_active", "auths_user"."date_joined", "auths_user"."id", "auths_user"."last_hierarchy_id", "auths_user"."last_module_id", "auths_user"."person_id", "auths_user"."updated_at", "auths_user"."registered_by" FROM "auths_user" WHERE "auths_user"."id" = '4c7e4779b6bd47198afbd9e574b13d0a'; args=('4c7e4779b6bd47198afbd9e574b13d0a',)
[2016-11-01 12:01:03] DEBUG [django.db.backends:89] (0.005) SELECT "django_session"."session_key", "django_session"."session_data", "django_session"."expire_date" FROM "django_session" WHERE ("django_session"."expire_date" > '2016-11-01 17:01:03.750491' AND "django_session"."session_key" = 'gtw0v45oztxiziavd0vcwh57etmeavi6'); args=('2016-11-01 17:01:03.750491', 'gtw0v45oztxiziavd0vcwh57etmeavi6')
[2016-11-01 12:01:03] DEBUG [django.db.backends:89] (0.001) SELECT "auths_user"."password", "auths_user"."last_login", "auths_user"."is_superuser", "auths_user"."username", "auths_user"."first_name", "auths_user"."last_name", "auths_user"."email", "auths_user"."is_staff", "auths_user"."is_active", "auths_user"."date_joined", "auths_user"."id", "auths_user"."last_hierarchy_id", "auths_user"."last_module_id", "auths_user"."person_id", "auths_user"."updated_at", "auths_user"."registered_by" FROM "auths_user" WHERE "auths_user"."id" = '4c7e4779b6bd47198afbd9e574b13d0a'; args=('4c7e4779b6bd47198afbd9e574b13d0a',)
[2016-11-01 12:01:03] DEBUG [django.db.backends:89] (0.000) BEGIN; args=None
[2016-11-01 12:01:03] DEBUG [django.db.backends:89] (0.001) SELECT (1) AS "a" FROM "catalogo_distribuidor" WHERE "catalogo_distribuidor"."ruc" = 23424 LIMIT 1; args=(23424,)
[2016-11-01 12:01:03] DEBUG [django.db.backends:89] (0.000) UPDATE "catalogo_distribuidor" SET "nombre" = 'SA', "ruc" = 23424, "telefono" = 35436, "direccion" = 'Jr. lima' WHERE "catalogo_distribuidor"."id" = '13a176d928d14e4fb8b3f26cdc11b346'; args=('SA', 23424, 35436, 'Jr. lima', '13a176d928d14e4fb8b3f26cdc11b346')
[2016-11-01 12:01:03] DEBUG [django.db.backends:89] (0.008) INSERT INTO "catalogo_distribuidor" ("id", "nombre", "ruc", "telefono", "direccion") SELECT '13a176d928d14e4fb8b3f26cdc11b346', 'SA', 23424, 35436, 'Jr. lima'; args=('13a176d928d14e4fb8b3f26cdc11b346', 'SA', 23424, 35436, 'Jr. lima')
[2016-11-01 12:01:03] DEBUG [django.db.backends:89] (0.000) INSERT INTO "django_admin_log" ("action_time", "user_id", "content_type_id", "object_id", "object_repr", "action_flag", "change_message") VALUES ('2016-11-01 17:01:03.773122', '4c7e4779b6bd47198afbd9e574b13d0a', 19, '13a176d9-28d1-4e4f-b8b3-f26cdc11b346', 'Distribuidor object', 1, 'Added.'); args=['2016-11-01 17:01:03.773122', '4c7e4779b6bd47198afbd9e574b13d0a', 19, '13a176d9-28d1-4e4f-b8b3-f26cdc11b346', 'Distribuidor object', 1, 'Added.']
[2016-11-01 12:01:04] DEBUG [django.template:927] Exception while resolving variable 'action' in template 'admin/popup_response.html'.
Traceback (most recent call last):
  File "D:\pydev\marketsoft\ve_market\lib\site-packages\django\template\base.py", line 883, in _resolve_lookup
    current = current[bit]
  File "D:\pydev\marketsoft\ve_market\lib\site-packages\django\template\context.py", line 77, in __getitem__
    raise KeyError(key)
KeyError: 'action'

During handling of the above exception, another exception occurred:

Traceback (most recent call last):
  File "D:\pydev\marketsoft\ve_market\lib\site-packages\django\template\base.py", line 889, in _resolve_lookup
    if isinstance(current, BaseContext) and getattr(type(current), bit):
AttributeError: type object 'Context' has no attribute 'action'

During handling of the above exception, another exception occurred:

Traceback (most recent call last):
  File "D:\pydev\marketsoft\ve_market\lib\site-packages\django\template\base.py", line 898, in _resolve_lookup
    current = current[int(bit)]
ValueError: invalid literal for int() with base 10: 'action'

During handling of the above exception, another exception occurred:

Traceback (most recent call last):
  File "D:\pydev\marketsoft\ve_market\lib\site-packages\django\template\base.py", line 905, in _resolve_lookup
    (bit, current))  # missing attribute
django.template.base.VariableDoesNotExist: Failed lookup for key [action] in "[{'True': True, 'False': False, 'None': None}, {'obj': <Distribuidor: Distribuidor object>, 'value': UUID('13a176d9-28d1-4e4f-b8b3-f26cdc11b346')}]"
[2016-11-01 12:01:04] DEBUG [django.template:927] Exception while resolving variable 'action' in template 'admin/popup_response.html'.
Traceback (most recent call last):
  File "D:\pydev\marketsoft\ve_market\lib\site-packages\django\template\base.py", line 883, in _resolve_lookup
    current = current[bit]
  File "D:\pydev\marketsoft\ve_market\lib\site-packages\django\template\context.py", line 77, in __getitem__
    raise KeyError(key)
KeyError: 'action'

During handling of the above exception, another exception occurred:

Traceback (most recent call last):
  File "D:\pydev\marketsoft\ve_market\lib\site-packages\django\template\base.py", line 889, in _resolve_lookup
    if isinstance(current, BaseContext) and getattr(type(current), bit):
AttributeError: type object 'Context' has no attribute 'action'

During handling of the above exception, another exception occurred:

Traceback (most recent call last):
  File "D:\pydev\marketsoft\ve_market\lib\site-packages\django\template\base.py", line 898, in _resolve_lookup
    current = current[int(bit)]
ValueError: invalid literal for int() with base 10: 'action'

During handling of the above exception, another exception occurred:

Traceback (most recent call last):
  File "D:\pydev\marketsoft\ve_market\lib\site-packages\django\template\base.py", line 905, in _resolve_lookup
    (bit, current))  # missing attribute
django.template.base.VariableDoesNotExist: Failed lookup for key [action] in "[{'True': True, 'False': False, 'None': None}, {'obj': <Distribuidor: Distribuidor object>, 'value': UUID('13a176d9-28d1-4e4f-b8b3-f26cdc11b346')}]"
